<robot name="advancedbot">

	 <link name="link_-1">
		<inertial>
			<origin xyz="0.0 0.0 -0.0455" rpy="0.0 0.0 0.0"/>
			<mass value="0.18181818181818182"/>
			<inertia ixx="0.0" ixy="0.0" ixz="0.0" iyy="0.0" iyz="0.0" izz="0.0"/>
		</inertial>
		<visual name="">
			<origin xyz="0.0 0.0 -0.0455" rpy="0.0 0.0 0.0"/>
			<geometry>
				<box size="0.1 0.1 0.045454545454545456"/>
			</geometry>
			<material name="">
				<color rgba="0.6 0.6 0.6 1.0"/>
				<texture filename=""/>
			</material>
		</visual>
		<collision>
			<origin xyz="0.0 0.0 -0.0455" rpy="0.0 0.0 0.0"/>
			<geometry>
				<box size="0.1 0.1 0.09090909090909091"/>
"/>
			</geometry>
		</collision>
	</link>

	<link name="link_0_x">
		<inertial>
			<origin xyz="0.0 0.0 0.0" rpy="0.0 0.0 0.0"/>
			<mass value="0.00001"/>
			<inertia ixx="0.0000001" ixy="0.0" ixz="0.0" iyy="0.0000001" iyz="0.0" izz="0.0000001"/>
		</inertial>
		<visual name="">
			<origin xyz="0.0 0.0 0.0" rpy="0.0 0.0 0.0"/>
			<geometry>
				<box size="0.1 0.1 0.1"/>
			</geometry>
			<material name="">
				<color rgba="0.6 0.6 0.6 1.0"/>
				<texture filename=""/>
			</material>
		</visual>
		<collision>
			<origin xyz="0.0 0.0 0.0" rpy="0.0 0.0 0.0"/>
			<geometry>
				<box size="0.1 0.1 0.045454545454545456"/>
			</geometry>
		</collision>
	</link>

	<link name="link_0_y">
		<inertial>
			<origin xyz="0.0 0.0 0.0" rpy="0.0 0.0 0.0"/>
			<mass value="0.00001"/>
			<inertia ixx="0.0000001" ixy="0.0" ixz="0.0" iyy="0.0000001" iyz="0.0" izz="0.0000001"/>
		</inertial>
		<visual name="">
			<origin xyz="0.0 0.0 0.0" rpy="0.0 0.0 0.0"/>
			<geometry>
				<box size="0.1 0.1 0.1"/>
			</geometry>
			<material name="">
				<color rgba="0.6 0.6 0.6 1.0"/>
				<texture filename=""/>
			</material>
		</visual>
		<collision>
			<origin xyz="0.0 0.0 0.0" rpy="0.0 0.0 0.0"/>
			<geometry>
				<box size="0.1 0.1 0.045454545454545456"/>
			</geometry>
		</collision>
	</link>

	<link name="link_0">
		<inertial>
			<origin xyz="0.0 0.0 -0.0455" rpy="0.0 0.0 0.0"/>
			<mass value="0.18181818181818182"/>
			<inertia ixx="0.0" ixy="0.0" ixz="0.0" iyy="0.0" iyz="0.0" izz="0.0"/>
		</inertial>
		<visual name="">
			<origin xyz="0.0 0.0 -0.0455" rpy="0.0 0.0 0.0"/>
			<geometry>
				<box size="0.09272727272727273 0.09272727272727273 0.045454545454545456"/>
			</geometry>
			<material name="">
				<color rgba="0.6 0.6 0.6 1.0"/>
				<texture filename=""/>
			</material>
		</visual>
		<collision>
			<origin xyz="0.0 0.0 -0.0455" rpy="0.0 0.0 0.0"/>
			<geometry>
				<box size="0.09272727272727273 0.09272727272727273 0.09090909090909091"/>
"/>
			</geometry>
		</collision>
	</link>

	<link name="link_1_x">
		<inertial>
			<origin xyz="0.0 0.0 0.0" rpy="0.0 0.0 0.0"/>
			<mass value="0.00001"/>
			<inertia ixx="0.0000001" ixy="0.0" ixz="0.0" iyy="0.0000001" iyz="0.0" izz="0.0000001"/>
		</inertial>
		<visual name="">
			<origin xyz="0.0 0.0 0.0" rpy="0.0 0.0 0.0"/>
			<geometry>
				<box size="0.09200000000000001 0.09200000000000001 0.09200000000000001"/>
			</geometry>
			<material name="">
				<color rgba="0.6 0.6 0.6 1.0"/>
				<texture filename=""/>
			</material>
		</visual>
		<collision>
			<origin xyz="0.0 0.0 0.0" rpy="0.0 0.0 0.0"/>
			<geometry>
				<box size="0.09200000000000001 0.09200000000000001 0.045454545454545456"/>
			</geometry>
		</collision>
	</link>

	<link name="link_1_y">
		<inertial>
			<origin xyz="0.0 0.0 0.0" rpy="0.0 0.0 0.0"/>
			<mass value="0.00001"/>
			<inertia ixx="0.0000001" ixy="0.0" ixz="0.0" iyy="0.0000001" iyz="0.0" izz="0.0000001"/>
		</inertial>
		<visual name="">
			<origin xyz="0.0 0.0 0.0" rpy="0.0 0.0 0.0"/>
			<geometry>
				<box size="0.09200000000000001 0.09200000000000001 0.09200000000000001"/>
			</geometry>
			<material name="">
				<color rgba="0.6 0.6 0.6 1.0"/>
				<texture filename=""/>
			</material>
		</visual>
		<collision>
			<origin xyz="0.0 0.0 0.0" rpy="0.0 0.0 0.0"/>
			<geometry>
				<box size="0.09200000000000001 0.09200000000000001 0.045454545454545456"/>
			</geometry>
		</collision>
	</link>

	<link name="link_1">
		<inertial>
			<origin xyz="0.0 0.0 -0.0455" rpy="0.0 0.0 0.0"/>
			<mass value="0.18181818181818182"/>
			<inertia ixx="0.0" ixy="0.0" ixz="0.0" iyy="0.0" iyz="0.0" izz="0.0"/>
		</inertial>
		<visual name="">
			<origin xyz="0.0 0.0 -0.0455" rpy="0.0 0.0 0.0"/>
			<geometry>
				<box size="0.08545454545454545 0.08545454545454545 0.045454545454545456"/>
			</geometry>
			<material name="">
				<color rgba="0.6 0.6 0.6 1.0"/>
				<texture filename=""/>
			</material>
		</visual>
		<collision>
			<origin xyz="0.0 0.0 -0.0455" rpy="0.0 0.0 0.0"/>
			<geometry>
				<box size="0.08545454545454545 0.08545454545454545 0.09090909090909091"/>
"/>
			</geometry>
		</collision>
	</link>

	<link name="link_2_x">
		<inertial>
			<origin xyz="0.0 0.0 0.0" rpy="0.0 0.0 0.0"/>
			<mass value="0.00001"/>
			<inertia ixx="0.0000001" ixy="0.0" ixz="0.0" iyy="0.0000001" iyz="0.0" izz="0.0000001"/>
		</inertial>
		<visual name="">
			<origin xyz="0.0 0.0 0.0" rpy="0.0 0.0 0.0"/>
			<geometry>
				<box size="0.08400000000000002 0.08400000000000002 0.08400000000000002"/>
			</geometry>
			<material name="">
				<color rgba="0.6 0.6 0.6 1.0"/>
				<texture filename=""/>
			</material>
		</visual>
		<collision>
			<origin xyz="0.0 0.0 0.0" rpy="0.0 0.0 0.0"/>
			<geometry>
				<box size="0.08400000000000002 0.08400000000000002 0.045454545454545456"/>
			</geometry>
		</collision>
	</link>

	<link name="link_2_y">
		<inertial>
			<origin xyz="0.0 0.0 0.0" rpy="0.0 0.0 0.0"/>
			<mass value="0.00001"/>
			<inertia ixx="0.0000001" ixy="0.0" ixz="0.0" iyy="0.0000001" iyz="0.0" izz="0.0000001"/>
		</inertial>
		<visual name="">
			<origin xyz="0.0 0.0 0.0" rpy="0.0 0.0 0.0"/>
			<geometry>
				<box size="0.08400000000000002 0.08400000000000002 0.08400000000000002"/>
			</geometry>
			<material name="">
				<color rgba="0.6 0.6 0.6 1.0"/>
				<texture filename=""/>
			</material>
		</visual>
		<collision>
			<origin xyz="0.0 0.0 0.0" rpy="0.0 0.0 0.0"/>
			<geometry>
				<box size="0.08400000000000002 0.08400000000000002 0.045454545454545456"/>
			</geometry>
		</collision>
	</link>

	<link name="link_2">
		<inertial>
			<origin xyz="0.0 0.0 -0.0455" rpy="0.0 0.0 0.0"/>
			<mass value="0.18181818181818182"/>
			<inertia ixx="0.0" ixy="0.0" ixz="0.0" iyy="0.0" iyz="0.0" izz="0.0"/>
		</inertial>
		<visual name="">
			<origin xyz="0.0 0.0 -0.0455" rpy="0.0 0.0 0.0"/>
			<geometry>
				<box size="0.07818181818181819 0.07818181818181819 0.045454545454545456"/>
			</geometry>
			<material name="">
				<color rgba="0.6 0.6 0.6 1.0"/>
				<texture filename=""/>
			</material>
		</visual>
		<collision>
			<origin xyz="0.0 0.0 -0.0455" rpy="0.0 0.0 0.0"/>
			<geometry>
				<box size="0.07818181818181819 0.07818181818181819 0.09090909090909091"/>
"/>
			</geometry>
		</collision>
	</link>

	<link name="link_3_x">
		<inertial>
			<origin xyz="0.0 0.0 0.0" rpy="0.0 0.0 0.0"/>
			<mass value="0.00001"/>
			<inertia ixx="0.0000001" ixy="0.0" ixz="0.0" iyy="0.0000001" iyz="0.0" izz="0.0000001"/>
		</inertial>
		<visual name="">
			<origin xyz="0.0 0.0 0.0" rpy="0.0 0.0 0.0"/>
			<geometry>
				<box size="0.076 0.076 0.076"/>
			</geometry>
			<material name="">
				<color rgba="0.6 0.6 0.6 1.0"/>
				<texture filename=""/>
			</material>
		</visual>
		<collision>
			<origin xyz="0.0 0.0 0.0" rpy="0.0 0.0 0.0"/>
			<geometry>
				<box size="0.076 0.076 0.045454545454545456"/>
			</geometry>
		</collision>
	</link>

	<link name="link_3_y">
		<inertial>
			<origin xyz="0.0 0.0 0.0" rpy="0.0 0.0 0.0"/>
			<mass value="0.00001"/>
			<inertia ixx="0.0000001" ixy="0.0" ixz="0.0" iyy="0.0000001" iyz="0.0" izz="0.0000001"/>
		</inertial>
		<visual name="">
			<origin xyz="0.0 0.0 0.0" rpy="0.0 0.0 0.0"/>
			<geometry>
				<box size="0.076 0.076 0.076"/>
			</geometry>
			<material name="">
				<color rgba="0.6 0.6 0.6 1.0"/>
				<texture filename=""/>
			</material>
		</visual>
		<collision>
			<origin xyz="0.0 0.0 0.0" rpy="0.0 0.0 0.0"/>
			<geometry>
				<box size="0.076 0.076 0.045454545454545456"/>
			</geometry>
		</collision>
	</link>

	<link name="link_3">
		<inertial>
			<origin xyz="0.0 0.0 -0.0455" rpy="0.0 0.0 0.0"/>
			<mass value="0.18181818181818182"/>
			<inertia ixx="0.0" ixy="0.0" ixz="0.0" iyy="0.0" iyz="0.0" izz="0.0"/>
		</inertial>
		<visual name="">
			<origin xyz="0.0 0.0 -0.0455" rpy="0.0 0.0 0.0"/>
			<geometry>
				<box size="0.07090909090909092 0.07090909090909092 0.045454545454545456"/>
			</geometry>
			<material name="">
				<color rgba="0.6 0.6 0.6 1.0"/>
				<texture filename=""/>
			</material>
		</visual>
		<collision>
			<origin xyz="0.0 0.0 -0.0455" rpy="0.0 0.0 0.0"/>
			<geometry>
				<box size="0.07090909090909092 0.07090909090909092 0.09090909090909091"/>
"/>
			</geometry>
		</collision>
	</link>

	<link name="link_4_x">
		<inertial>
			<origin xyz="0.0 0.0 0.0" rpy="0.0 0.0 0.0"/>
			<mass value="0.00001"/>
			<inertia ixx="0.0000001" ixy="0.0" ixz="0.0" iyy="0.0000001" iyz="0.0" izz="0.0000001"/>
		</inertial>
		<visual name="">
			<origin xyz="0.0 0.0 0.0" rpy="0.0 0.0 0.0"/>
			<geometry>
				<box size="0.068 0.068 0.068"/>
			</geometry>
			<material name="">
				<color rgba="0.6 0.6 0.6 1.0"/>
				<texture filename=""/>
			</material>
		</visual>
		<collision>
			<origin xyz="0.0 0.0 0.0" rpy="0.0 0.0 0.0"/>
			<geometry>
				<box size="0.068 0.068 0.045454545454545456"/>
			</geometry>
		</collision>
	</link>

	<link name="link_4_y">
		<inertial>
			<origin xyz="0.0 0.0 0.0" rpy="0.0 0.0 0.0"/>
			<mass value="0.00001"/>
			<inertia ixx="0.0000001" ixy="0.0" ixz="0.0" iyy="0.0000001" iyz="0.0" izz="0.0000001"/>
		</inertial>
		<visual name="">
			<origin xyz="0.0 0.0 0.0" rpy="0.0 0.0 0.0"/>
			<geometry>
				<box size="0.068 0.068 0.068"/>
			</geometry>
			<material name="">
				<color rgba="0.6 0.6 0.6 1.0"/>
				<texture filename=""/>
			</material>
		</visual>
		<collision>
			<origin xyz="0.0 0.0 0.0" rpy="0.0 0.0 0.0"/>
			<geometry>
				<box size="0.068 0.068 0.045454545454545456"/>
			</geometry>
		</collision>
	</link>

	<link name="link_4">
		<inertial>
			<origin xyz="0.0 0.0 -0.0455" rpy="0.0 0.0 0.0"/>
			<mass value="0.18181818181818182"/>
			<inertia ixx="0.0" ixy="0.0" ixz="0.0" iyy="0.0" iyz="0.0" izz="0.0"/>
		</inertial>
		<visual name="">
			<origin xyz="0.0 0.0 -0.0455" rpy="0.0 0.0 0.0"/>
			<geometry>
				<box size="0.06363636363636363 0.06363636363636363 0.045454545454545456"/>
			</geometry>
			<material name="">
				<color rgba="0.6 0.6 0.6 1.0"/>
				<texture filename=""/>
			</material>
		</visual>
		<collision>
			<origin xyz="0.0 0.0 -0.0455" rpy="0.0 0.0 0.0"/>
			<geometry>
				<box size="0.06363636363636363 0.06363636363636363 0.09090909090909091"/>
"/>
			</geometry>
		</collision>
	</link>

	<link name="link_5_x">
		<inertial>
			<origin xyz="0.0 0.0 0.0" rpy="0.0 0.0 0.0"/>
			<mass value="0.00001"/>
			<inertia ixx="0.0000001" ixy="0.0" ixz="0.0" iyy="0.0000001" iyz="0.0" izz="0.0000001"/>
		</inertial>
		<visual name="">
			<origin xyz="0.0 0.0 0.0" rpy="0.0 0.0 0.0"/>
			<geometry>
				<box size="0.060000000000000005 0.060000000000000005 0.060000000000000005"/>
			</geometry>
			<material name="">
				<color rgba="0.6 0.6 0.6 1.0"/>
				<texture filename=""/>
			</material>
		</visual>
		<collision>
			<origin xyz="0.0 0.0 0.0" rpy="0.0 0.0 0.0"/>
			<geometry>
				<box size="0.060000000000000005 0.060000000000000005 0.045454545454545456"/>
			</geometry>
		</collision>
	</link>

	<link name="link_5_y">
		<inertial>
			<origin xyz="0.0 0.0 0.0" rpy="0.0 0.0 0.0"/>
			<mass value="0.00001"/>
			<inertia ixx="0.0000001" ixy="0.0" ixz="0.0" iyy="0.0000001" iyz="0.0" izz="0.0000001"/>
		</inertial>
		<visual name="">
			<origin xyz="0.0 0.0 0.0" rpy="0.0 0.0 0.0"/>
			<geometry>
				<box size="0.060000000000000005 0.060000000000000005 0.060000000000000005"/>
			</geometry>
			<material name="">
				<color rgba="0.6 0.6 0.6 1.0"/>
				<texture filename=""/>
			</material>
		</visual>
		<collision>
			<origin xyz="0.0 0.0 0.0" rpy="0.0 0.0 0.0"/>
			<geometry>
				<box size="0.060000000000000005 0.060000000000000005 0.045454545454545456"/>
			</geometry>
		</collision>
	</link>

	<link name="link_5">
		<inertial>
			<origin xyz="0.0 0.0 -0.0455" rpy="0.0 0.0 0.0"/>
			<mass value="0.18181818181818182"/>
			<inertia ixx="0.0" ixy="0.0" ixz="0.0" iyy="0.0" iyz="0.0" izz="0.0"/>
		</inertial>
		<visual name="">
			<origin xyz="0.0 0.0 -0.0455" rpy="0.0 0.0 0.0"/>
			<geometry>
				<box size="0.05636363636363637 0.05636363636363637 0.045454545454545456"/>
			</geometry>
			<material name="">
				<color rgba="0.6 0.6 0.6 1.0"/>
				<texture filename=""/>
			</material>
		</visual>
		<collision>
			<origin xyz="0.0 0.0 -0.0455" rpy="0.0 0.0 0.0"/>
			<geometry>
				<box size="0.05636363636363637 0.05636363636363637 0.09090909090909091"/>
"/>
			</geometry>
		</collision>
	</link>

	<link name="link_6_x">
		<inertial>
			<origin xyz="0.0 0.0 0.0" rpy="0.0 0.0 0.0"/>
			<mass value="0.00001"/>
			<inertia ixx="0.0000001" ixy="0.0" ixz="0.0" iyy="0.0000001" iyz="0.0" izz="0.0000001"/>
		</inertial>
		<visual name="">
			<origin xyz="0.0 0.0 0.0" rpy="0.0 0.0 0.0"/>
			<geometry>
				<box size="0.052000000000000005 0.052000000000000005 0.052000000000000005"/>
			</geometry>
			<material name="">
				<color rgba="0.6 0.6 0.6 1.0"/>
				<texture filename=""/>
			</material>
		</visual>
		<collision>
			<origin xyz="0.0 0.0 0.0" rpy="0.0 0.0 0.0"/>
			<geometry>
				<box size="0.052000000000000005 0.052000000000000005 0.045454545454545456"/>
			</geometry>
		</collision>
	</link>

	<link name="link_6_y">
		<inertial>
			<origin xyz="0.0 0.0 0.0" rpy="0.0 0.0 0.0"/>
			<mass value="0.00001"/>
			<inertia ixx="0.0000001" ixy="0.0" ixz="0.0" iyy="0.0000001" iyz="0.0" izz="0.0000001"/>
		</inertial>
		<visual name="">
			<origin xyz="0.0 0.0 0.0" rpy="0.0 0.0 0.0"/>
			<geometry>
				<box size="0.052000000000000005 0.052000000000000005 0.052000000000000005"/>
			</geometry>
			<material name="">
				<color rgba="0.6 0.6 0.6 1.0"/>
				<texture filename=""/>
			</material>
		</visual>
		<collision>
			<origin xyz="0.0 0.0 0.0" rpy="0.0 0.0 0.0"/>
			<geometry>
				<box size="0.052000000000000005 0.052000000000000005 0.045454545454545456"/>
			</geometry>
		</collision>
	</link>

	<link name="link_6">
		<inertial>
			<origin xyz="0.0 0.0 -0.0455" rpy="0.0 0.0 0.0"/>
			<mass value="0.18181818181818182"/>
			<inertia ixx="0.0" ixy="0.0" ixz="0.0" iyy="0.0" iyz="0.0" izz="0.0"/>
		</inertial>
		<visual name="">
			<origin xyz="0.0 0.0 -0.0455" rpy="0.0 0.0 0.0"/>
			<geometry>
				<box size="0.049090909090909095 0.049090909090909095 0.045454545454545456"/>
			</geometry>
			<material name="">
				<color rgba="0.6 0.6 0.6 1.0"/>
				<texture filename=""/>
			</material>
		</visual>
		<collision>
			<origin xyz="0.0 0.0 -0.0455" rpy="0.0 0.0 0.0"/>
			<geometry>
				<box size="0.049090909090909095 0.049090909090909095 0.09090909090909091"/>
"/>
			</geometry>
		</collision>
	</link>

	<link name="link_7_x">
		<inertial>
			<origin xyz="0.0 0.0 0.0" rpy="0.0 0.0 0.0"/>
			<mass value="0.00001"/>
			<inertia ixx="0.0000001" ixy="0.0" ixz="0.0" iyy="0.0000001" iyz="0.0" izz="0.0000001"/>
		</inertial>
		<visual name="">
			<origin xyz="0.0 0.0 0.0" rpy="0.0 0.0 0.0"/>
			<geometry>
				<box size="0.044000000000000004 0.044000000000000004 0.044000000000000004"/>
			</geometry>
			<material name="">
				<color rgba="0.6 0.6 0.6 1.0"/>
				<texture filename=""/>
			</material>
		</visual>
		<collision>
			<origin xyz="0.0 0.0 0.0" rpy="0.0 0.0 0.0"/>
			<geometry>
				<box size="0.044000000000000004 0.044000000000000004 0.045454545454545456"/>
			</geometry>
		</collision>
	</link>

	<link name="link_7_y">
		<inertial>
			<origin xyz="0.0 0.0 0.0" rpy="0.0 0.0 0.0"/>
			<mass value="0.00001"/>
			<inertia ixx="0.0000001" ixy="0.0" ixz="0.0" iyy="0.0000001" iyz="0.0" izz="0.0000001"/>
		</inertial>
		<visual name="">
			<origin xyz="0.0 0.0 0.0" rpy="0.0 0.0 0.0"/>
			<geometry>
				<box size="0.044000000000000004 0.044000000000000004 0.044000000000000004"/>
			</geometry>
			<material name="">
				<color rgba="0.6 0.6 0.6 1.0"/>
				<texture filename=""/>
			</material>
		</visual>
		<collision>
			<origin xyz="0.0 0.0 0.0" rpy="0.0 0.0 0.0"/>
			<geometry>
				<box size="0.044000000000000004 0.044000000000000004 0.045454545454545456"/>
			</geometry>
		</collision>
	</link>

	<link name="link_7">
		<inertial>
			<origin xyz="0.0 0.0 -0.0455" rpy="0.0 0.0 0.0"/>
			<mass value="0.18181818181818182"/>
			<inertia ixx="0.0" ixy="0.0" ixz="0.0" iyy="0.0" iyz="0.0" izz="0.0"/>
		</inertial>
		<visual name="">
			<origin xyz="0.0 0.0 -0.0455" rpy="0.0 0.0 0.0"/>
			<geometry>
				<box size="0.04181818181818182 0.04181818181818182 0.045454545454545456"/>
			</geometry>
			<material name="">
				<color rgba="0.6 0.6 0.6 1.0"/>
				<texture filename=""/>
			</material>
		</visual>
		<collision>
			<origin xyz="0.0 0.0 -0.0455" rpy="0.0 0.0 0.0"/>
			<geometry>
				<box size="0.04181818181818182 0.04181818181818182 0.09090909090909091"/>
"/>
			</geometry>
		</collision>
	</link>

	<link name="link_8_x">
		<inertial>
			<origin xyz="0.0 0.0 0.0" rpy="0.0 0.0 0.0"/>
			<mass value="0.00001"/>
			<inertia ixx="0.0000001" ixy="0.0" ixz="0.0" iyy="0.0000001" iyz="0.0" izz="0.0000001"/>
		</inertial>
		<visual name="">
			<origin xyz="0.0 0.0 0.0" rpy="0.0 0.0 0.0"/>
			<geometry>
				<box size="0.036 0.036 0.036"/>
			</geometry>
			<material name="">
				<color rgba="0.6 0.6 0.6 1.0"/>
				<texture filename=""/>
			</material>
		</visual>
		<collision>
			<origin xyz="0.0 0.0 0.0" rpy="0.0 0.0 0.0"/>
			<geometry>
				<box size="0.036 0.036 0.045454545454545456"/>
			</geometry>
		</collision>
	</link>

	<link name="link_8_y">
		<inertial>
			<origin xyz="0.0 0.0 0.0" rpy="0.0 0.0 0.0"/>
			<mass value="0.00001"/>
			<inertia ixx="0.0000001" ixy="0.0" ixz="0.0" iyy="0.0000001" iyz="0.0" izz="0.0000001"/>
		</inertial>
		<visual name="">
			<origin xyz="0.0 0.0 0.0" rpy="0.0 0.0 0.0"/>
			<geometry>
				<box size="0.036 0.036 0.036"/>
			</geometry>
			<material name="">
				<color rgba="0.6 0.6 0.6 1.0"/>
				<texture filename=""/>
			</material>
		</visual>
		<collision>
			<origin xyz="0.0 0.0 0.0" rpy="0.0 0.0 0.0"/>
			<geometry>
				<box size="0.036 0.036 0.045454545454545456"/>
			</geometry>
		</collision>
	</link>

	<link name="link_8">
		<inertial>
			<origin xyz="0.0 0.0 -0.0455" rpy="0.0 0.0 0.0"/>
			<mass value="0.18181818181818182"/>
			<inertia ixx="0.0" ixy="0.0" ixz="0.0" iyy="0.0" iyz="0.0" izz="0.0"/>
		</inertial>
		<visual name="">
			<origin xyz="0.0 0.0 -0.0455" rpy="0.0 0.0 0.0"/>
			<geometry>
				<box size="0.034545454545454546 0.034545454545454546 0.045454545454545456"/>
			</geometry>
			<material name="">
				<color rgba="0.6 0.6 0.6 1.0"/>
				<texture filename=""/>
			</material>
		</visual>
		<collision>
			<origin xyz="0.0 0.0 -0.0455" rpy="0.0 0.0 0.0"/>
			<geometry>
				<box size="0.034545454545454546 0.034545454545454546 0.09090909090909091"/>
"/>
			</geometry>
		</collision>
	</link>

	<link name="link_9_x">
		<inertial>
			<origin xyz="0.0 0.0 0.0" rpy="0.0 0.0 0.0"/>
			<mass value="0.00001"/>
			<inertia ixx="0.0000001" ixy="0.0" ixz="0.0" iyy="0.0000001" iyz="0.0" izz="0.0000001"/>
		</inertial>
		<visual name="">
			<origin xyz="0.0 0.0 0.0" rpy="0.0 0.0 0.0"/>
			<geometry>
				<box size="0.028 0.028 0.028"/>
			</geometry>
			<material name="">
				<color rgba="0.6 0.6 0.6 1.0"/>
				<texture filename=""/>
			</material>
		</visual>
		<collision>
			<origin xyz="0.0 0.0 0.0" rpy="0.0 0.0 0.0"/>
			<geometry>
				<box size="0.028 0.028 0.045454545454545456"/>
			</geometry>
		</collision>
	</link>

	<link name="link_9_y">
		<inertial>
			<origin xyz="0.0 0.0 0.0" rpy="0.0 0.0 0.0"/>
			<mass value="0.00001"/>
			<inertia ixx="0.0000001" ixy="0.0" ixz="0.0" iyy="0.0000001" iyz="0.0" izz="0.0000001"/>
		</inertial>
		<visual name="">
			<origin xyz="0.0 0.0 0.0" rpy="0.0 0.0 0.0"/>
			<geometry>
				<box size="0.028 0.028 0.028"/>
			</geometry>
			<material name="">
				<color rgba="0.6 0.6 0.6 1.0"/>
				<texture filename=""/>
			</material>
		</visual>
		<collision>
			<origin xyz="0.0 0.0 0.0" rpy="0.0 0.0 0.0"/>
			<geometry>
				<box size="0.028 0.028 0.045454545454545456"/>
			</geometry>
		</collision>
	</link>

	<link name="link_9">
		<inertial>
			<origin xyz="0.0 0.0 -0.0455" rpy="0.0 0.0 0.0"/>
			<mass value="0.18181818181818182"/>
			<inertia ixx="0.0" ixy="0.0" ixz="0.0" iyy="0.0" iyz="0.0" izz="0.0"/>
		</inertial>
		<visual name="">
			<origin xyz="0.0 0.0 -0.0455" rpy="0.0 0.0 0.0"/>
			<geometry>
				<box size="0.027272727272727275 0.027272727272727275 0.045454545454545456"/>
			</geometry>
			<material name="">
				<color rgba="0.6 0.6 0.6 1.0"/>
				<texture filename=""/>
			</material>
		</visual>
		<collision>
			<origin xyz="0.0 0.0 -0.0455" rpy="0.0 0.0 0.0"/>
			<geometry>
				<box size="0.027272727272727275 0.027272727272727275 0.09090909090909091"/>
"/>
			</geometry>
		</collision>
	</link>

	<joint name="joint_0_x" type="revolute">
		<origin xyz="0.0 0.0 -0.0909" rpy="0.0 0.0 0.0"/>
		<parent link="link_-1"/>
		<child link="link_0_x"/>
		<axis xyz="1.0 0.0 0.0"/>
		<limit lower="-1.57" upper="1.57" effort="1000" velocity="20"/>
		<dynamics damping="0.05"/>
	</joint>

	<joint name="joint_0_y" type="revolute">
		<origin xyz="0.0 0.0 0.0" rpy="0.0 0.0 0.0"/>
		<parent link="link_0_x"/>
		<child link="link_0_y"/>
		<axis xyz="0.0 1.0 0.0"/>
		<limit lower="-1.57" upper="1.57" effort="1000" velocity="20"/>
		<dynamics damping="0.05"/>
	</joint>

	<joint name="joint_0_z" type="continuous">
		<origin xyz="0.0 0.0 0.0" rpy="0.0 0.0 0.0"/>
		<parent link="link_0_y"/>
		<child link="link_0"/>
		<axis xyz="0.0 0.0 1.0"/>
		<dynamics damping="0.05"/>
	</joint>

	<joint name="joint_1_x" type="revolute">
		<origin xyz="0.0 0.0 -0.0909" rpy="0.0 0.0 0.0"/>
		<parent link="link_0"/>
		<child link="link_1_x"/>
		<axis xyz="1.0 0.0 0.0"/>
		<limit lower="-1.57" upper="1.57" effort="1000" velocity="20"/>
		<dynamics damping="0.05"/>
	</joint>

	<joint name="joint_1_y" type="revolute">
		<origin xyz="0.0 0.0 0.0" rpy="0.0 0.0 0.0"/>
		<parent link="link_1_x"/>
		<child link="link_1_y"/>
		<axis xyz="0.0 1.0 0.0"/>
		<limit lower="-1.57" upper="1.57" effort="1000" velocity="20"/>
		<dynamics damping="0.05"/>
	</joint>

	<joint name="joint_1_z" type="continuous">
		<origin xyz="0.0 0.0 0.0" rpy="0.0 0.0 0.0"/>
		<parent link="link_1_y"/>
		<child link="link_1"/>
		<axis xyz="0.0 0.0 1.0"/>
		<dynamics damping="0.05"/>
	</joint>

	<joint name="joint_2_x" type="revolute">
		<origin xyz="0.0 0.0 -0.0909" rpy="0.0 0.0 0.0"/>
		<parent link="link_1"/>
		<child link="link_2_x"/>
		<axis xyz="1.0 0.0 0.0"/>
		<limit lower="-1.57" upper="1.57" effort="1000" velocity="20"/>
		<dynamics damping="0.05"/>
	</joint>

	<joint name="joint_2_y" type="revolute">
		<origin xyz="0.0 0.0 0.0" rpy="0.0 0.0 0.0"/>
		<parent link="link_2_x"/>
		<child link="link_2_y"/>
		<axis xyz="0.0 1.0 0.0"/>
		<limit lower="-1.57" upper="1.57" effort="1000" velocity="20"/>
		<dynamics damping="0.05"/>
	</joint>

	<joint name="joint_2_z" type="continuous">
		<origin xyz="0.0 0.0 0.0" rpy="0.0 0.0 0.0"/>
		<parent link="link_2_y"/>
		<child link="link_2"/>
		<axis xyz="0.0 0.0 1.0"/>
		<dynamics damping="0.05"/>
	</joint>

	<joint name="joint_3_x" type="revolute">
		<origin xyz="0.0 0.0 -0.0909" rpy="0.0 0.0 0.0"/>
		<parent link="link_2"/>
		<child link="link_3_x"/>
		<axis xyz="1.0 0.0 0.0"/>
		<limit lower="-1.57" upper="1.57" effort="1000" velocity="20"/>
		<dynamics damping="0.05"/>
	</joint>

	<joint name="joint_3_y" type="revolute">
		<origin xyz="0.0 0.0 0.0" rpy="0.0 0.0 0.0"/>
		<parent link="link_3_x"/>
		<child link="link_3_y"/>
		<axis xyz="0.0 1.0 0.0"/>
		<limit lower="-1.57" upper="1.57" effort="1000" velocity="20"/>
		<dynamics damping="0.05"/>
	</joint>

	<joint name="joint_3_z" type="continuous">
		<origin xyz="0.0 0.0 0.0" rpy="0.0 0.0 0.0"/>
		<parent link="link_3_y"/>
		<child link="link_3"/>
		<axis xyz="0.0 0.0 1.0"/>
		<dynamics damping="0.05"/>
	</joint>

	<joint name="joint_4_x" type="revolute">
		<origin xyz="0.0 0.0 -0.0909" rpy="0.0 0.0 0.0"/>
		<parent link="link_3"/>
		<child link="link_4_x"/>
		<axis xyz="1.0 0.0 0.0"/>
		<limit lower="-1.57" upper="1.57" effort="1000" velocity="20"/>
		<dynamics damping="0.05"/>
	</joint>

	<joint name="joint_4_y" type="revolute">
		<origin xyz="0.0 0.0 0.0" rpy="0.0 0.0 0.0"/>
		<parent link="link_4_x"/>
		<child link="link_4_y"/>
		<axis xyz="0.0 1.0 0.0"/>
		<limit lower="-1.57" upper="1.57" effort="1000" velocity="20"/>
		<dynamics damping="0.05"/>
	</joint>

	<joint name="joint_4_z" type="continuous">
		<origin xyz="0.0 0.0 0.0" rpy="0.0 0.0 0.0"/>
		<parent link="link_4_y"/>
		<child link="link_4"/>
		<axis xyz="0.0 0.0 1.0"/>
		<dynamics damping="0.05"/>
	</joint>

	<joint name="joint_5_x" type="revolute">
		<origin xyz="0.0 0.0 -0.0909" rpy="0.0 0.0 0.0"/>
		<parent link="link_4"/>
		<child link="link_5_x"/>
		<axis xyz="1.0 0.0 0.0"/>
		<limit lower="-1.57" upper="1.57" effort="1000" velocity="20"/>
		<dynamics damping="0.05"/>
	</joint>

	<joint name="joint_5_y" type="revolute">
		<origin xyz="0.0 0.0 0.0" rpy="0.0 0.0 0.0"/>
		<parent link="link_5_x"/>
		<child link="link_5_y"/>
		<axis xyz="0.0 1.0 0.0"/>
		<limit lower="-1.57" upper="1.57" effort="1000" velocity="20"/>
		<dynamics damping="0.05"/>
	</joint>

	<joint name="joint_5_z" type="continuous">
		<origin xyz="0.0 0.0 0.0" rpy="0.0 0.0 0.0"/>
		<parent link="link_5_y"/>
		<child link="link_5"/>
		<axis xyz="0.0 0.0 1.0"/>
		<dynamics damping="0.05"/>
	</joint>

	<joint name="joint_6_x" type="revolute">
		<origin xyz="0.0 0.0 -0.0909" rpy="0.0 0.0 0.0"/>
		<parent link="link_5"/>
		<child link="link_6_x"/>
		<axis xyz="1.0 0.0 0.0"/>
		<limit lower="-1.57" upper="1.57" effort="1000" velocity="20"/>
		<dynamics damping="0.05"/>
	</joint>

	<joint name="joint_6_y" type="revolute">
		<origin xyz="0.0 0.0 0.0" rpy="0.0 0.0 0.0"/>
		<parent link="link_6_x"/>
		<child link="link_6_y"/>
		<axis xyz="0.0 1.0 0.0"/>
		<limit lower="-1.57" upper="1.57" effort="1000" velocity="20"/>
		<dynamics damping="0.05"/>
	</joint>

	<joint name="joint_6_z" type="continuous">
		<origin xyz="0.0 0.0 0.0" rpy="0.0 0.0 0.0"/>
		<parent link="link_6_y"/>
		<child link="link_6"/>
		<axis xyz="0.0 0.0 1.0"/>
		<dynamics damping="0.05"/>
	</joint>

	<joint name="joint_7_x" type="revolute">
		<origin xyz="0.0 0.0 -0.0909" rpy="0.0 0.0 0.0"/>
		<parent link="link_6"/>
		<child link="link_7_x"/>
		<axis xyz="1.0 0.0 0.0"/>
		<limit lower="-1.57" upper="1.57" effort="1000" velocity="20"/>
		<dynamics damping="0.05"/>
	</joint>

	<joint name="joint_7_y" type="revolute">
		<origin xyz="0.0 0.0 0.0" rpy="0.0 0.0 0.0"/>
		<parent link="link_7_x"/>
		<child link="link_7_y"/>
		<axis xyz="0.0 1.0 0.0"/>
		<limit lower="-1.57" upper="1.57" effort="1000" velocity="20"/>
		<dynamics damping="0.05"/>
	</joint>

	<joint name="joint_7_z" type="continuous">
		<origin xyz="0.0 0.0 0.0" rpy="0.0 0.0 0.0"/>
		<parent link="link_7_y"/>
		<child link="link_7"/>
		<axis xyz="0.0 0.0 1.0"/>
		<dynamics damping="0.05"/>
	</joint>

	<joint name="joint_8_x" type="revolute">
		<origin xyz="0.0 0.0 -0.0909" rpy="0.0 0.0 0.0"/>
		<parent link="link_7"/>
		<child link="link_8_x"/>
		<axis xyz="1.0 0.0 0.0"/>
		<limit lower="-1.57" upper="1.57" effort="1000" velocity="20"/>
		<dynamics damping="0.05"/>
	</joint>

	<joint name="joint_8_y" type="revolute">
		<origin xyz="0.0 0.0 0.0" rpy="0.0 0.0 0.0"/>
		<parent link="link_8_x"/>
		<child link="link_8_y"/>
		<axis xyz="0.0 1.0 0.0"/>
		<limit lower="-1.57" upper="1.57" effort="1000" velocity="20"/>
		<dynamics damping="0.05"/>
	</joint>

	<joint name="joint_8_z" type="continuous">
		<origin xyz="0.0 0.0 0.0" rpy="0.0 0.0 0.0"/>
		<parent link="link_8_y"/>
		<child link="link_8"/>
		<axis xyz="0.0 0.0 1.0"/>
		<dynamics damping="0.05"/>
	</joint>

	<joint name="joint_9_x" type="revolute">
		<origin xyz="0.0 0.0 -0.0909" rpy="0.0 0.0 0.0"/>
		<parent link="link_8"/>
		<child link="link_9_x"/>
		<axis xyz="1.0 0.0 0.0"/>
		<limit lower="-1.57" upper="1.57" effort="1000" velocity="20"/>
		<dynamics damping="0.05"/>
	</joint>

	<joint name="joint_9_y" type="revolute">
		<origin xyz="0.0 0.0 0.0" rpy="0.0 0.0 0.0"/>
		<parent link="link_9_x"/>
		<child link="link_9_y"/>
		<axis xyz="0.0 1.0 0.0"/>
		<limit lower="-1.57" upper="1.57" effort="1000" velocity="20"/>
		<dynamics damping="0.05"/>
	</joint>

	<joint name="joint_9_z" type="continuous">
		<origin xyz="0.0 0.0 0.0" rpy="0.0 0.0 0.0"/>
		<parent link="link_9_y"/>
		<child link="link_9"/>
		<axis xyz="0.0 0.0 1.0"/>
		<dynamics damping="0.05"/>
	</joint>

</robot>