<robot name="examplebot1">

	 <link name="link_-1">
		<inertial>
			<origin xyz="0.0 0.0 -0.025" rpy="0.0 0.0 0.0"/>
			<mass value="0.1"/>
			<inertia ixx="0.0" ixy="0.0" ixz="0.0" iyy="0.0" iyz="0.0" izz="0.0"/>
		</inertial>
		<visual name="">
			<origin xyz="0.0 0.0 -0.025" rpy="0.0 0.0 0.0"/>
			<geometry>
				<cylinder radius="0.05" length="0.05"/>
			</geometry>
			<material name="">
				<color rgba="0.6 0.6 0.6 1.0"/>
				<texture filename=""/>
			</material>
		</visual>
		<collision>
			<origin xyz="0.0 0.0 -0.025" rpy="0.0 0.0 0.0"/>
			<geometry>
				<cylinder radius="0.05" length="0.05"/>
			</geometry>
		</collision>
	</link>

	<link name="link_0_x">
		<inertial>
			<origin xyz="0.0 0.0 0.0" rpy="0.0 0.0 0.0"/>
			<mass value="0.00001"/>
			<inertia ixx="0.0000001" ixy="0.0" ixz="0.0" iyy="0.0000001" iyz="0.0" izz="0.0000001"/>
		</inertial>
		<visual name="">
			<origin xyz="0.0 0.0 0.0" rpy="0.0 0.0 0.0"/>
			<geometry>
				<sphere radius="0.05"/>
			</geometry>
			<material name="">
				<color rgba="0.6 0.6 0.6 1.0"/>
				<texture filename=""/>
			</material>
		</visual>
		<collision>
			<origin xyz="0.0 0.0 0.0" rpy="0.0 0.0 0.0"/>
			<geometry>
				<sphere radius="0.05"/>
			</geometry>
		</collision>
	</link>

	<link name="link_0_y">
		<inertial>
			<origin xyz="0.0 0.0 0.0" rpy="0.0 0.0 0.0"/>
			<mass value="0.00001"/>
			<inertia ixx="0.0000001" ixy="0.0" ixz="0.0" iyy="0.0000001" iyz="0.0" izz="0.0000001"/>
		</inertial>
		<visual name="">
			<origin xyz="0.0 0.0 0.0" rpy="0.0 0.0 0.0"/>
			<geometry>
				<sphere radius="0.05"/>
			</geometry>
			<material name="">
				<color rgba="0.6 0.6 0.6 1.0"/>
				<texture filename=""/>
			</material>
		</visual>
		<collision>
			<origin xyz="0.0 0.0 0.0" rpy="0.0 0.0 0.0"/>
			<geometry>
				<sphere radius="0.05"/>
			</geometry>
		</collision>
	</link>

	<link name="link_0">
		<inertial>
			<origin xyz="0.0 0.0 -0.025" rpy="0.0 0.0 0.0"/>
			<mass value="0.1"/>
			<inertia ixx="0.0" ixy="0.0" ixz="0.0" iyy="0.0" iyz="0.0" izz="0.0"/>
		</inertial>
		<visual name="">
			<origin xyz="0.0 0.0 -0.025" rpy="0.0 0.0 0.0"/>
			<geometry>
				<cylinder radius="0.05" length="0.05"/>
			</geometry>
			<material name="">
				<color rgba="0.6 0.6 0.6 1.0"/>
				<texture filename=""/>
			</material>
		</visual>
		<collision>
			<origin xyz="0.0 0.0 -0.025" rpy="0.0 0.0 0.0"/>
			<geometry>
				<cylinder radius="0.05" length="0.05"/>
			</geometry>
		</collision>
	</link>

	<link name="link_1_x">
		<inertial>
			<origin xyz="0.0 0.0 0.0" rpy="0.0 0.0 0.0"/>
			<mass value="0.00001"/>
			<inertia ixx="0.0000001" ixy="0.0" ixz="0.0" iyy="0.0000001" iyz="0.0" izz="0.0000001"/>
		</inertial>
		<visual name="">
			<origin xyz="0.0 0.0 0.0" rpy="0.0 0.0 0.0"/>
			<geometry>
				<sphere radius="0.05"/>
			</geometry>
			<material name="">
				<color rgba="0.6 0.6 0.6 1.0"/>
				<texture filename=""/>
			</material>
		</visual>
		<collision>
			<origin xyz="0.0 0.0 0.0" rpy="0.0 0.0 0.0"/>
			<geometry>
				<sphere radius="0.05"/>
			</geometry>
		</collision>
	</link>

	<link name="link_1_y">
		<inertial>
			<origin xyz="0.0 0.0 0.0" rpy="0.0 0.0 0.0"/>
			<mass value="0.00001"/>
			<inertia ixx="0.0000001" ixy="0.0" ixz="0.0" iyy="0.0000001" iyz="0.0" izz="0.0000001"/>
		</inertial>
		<visual name="">
			<origin xyz="0.0 0.0 0.0" rpy="0.0 0.0 0.0"/>
			<geometry>
				<sphere radius="0.05"/>
			</geometry>
			<material name="">
				<color rgba="0.6 0.6 0.6 1.0"/>
				<texture filename=""/>
			</material>
		</visual>
		<collision>
			<origin xyz="0.0 0.0 0.0" rpy="0.0 0.0 0.0"/>
			<geometry>
				<sphere radius="0.05"/>
			</geometry>
		</collision>
	</link>

	<link name="link_1">
		<inertial>
			<origin xyz="0.0 0.0 -0.025" rpy="0.0 0.0 0.0"/>
			<mass value="0.1"/>
			<inertia ixx="0.0" ixy="0.0" ixz="0.0" iyy="0.0" iyz="0.0" izz="0.0"/>
		</inertial>
		<visual name="">
			<origin xyz="0.0 0.0 -0.025" rpy="0.0 0.0 0.0"/>
			<geometry>
				<cylinder radius="0.05" length="0.05"/>
			</geometry>
			<material name="">
				<color rgba="0.6 0.6 0.6 1.0"/>
				<texture filename=""/>
			</material>
		</visual>
		<collision>
			<origin xyz="0.0 0.0 -0.025" rpy="0.0 0.0 0.0"/>
			<geometry>
				<cylinder radius="0.05" length="0.05"/>
			</geometry>
		</collision>
	</link>

	<link name="link_2_x">
		<inertial>
			<origin xyz="0.0 0.0 0.0" rpy="0.0 0.0 0.0"/>
			<mass value="0.00001"/>
			<inertia ixx="0.0000001" ixy="0.0" ixz="0.0" iyy="0.0000001" iyz="0.0" izz="0.0000001"/>
		</inertial>
		<visual name="">
			<origin xyz="0.0 0.0 0.0" rpy="0.0 0.0 0.0"/>
			<geometry>
				<sphere radius="0.05"/>
			</geometry>
			<material name="">
				<color rgba="0.6 0.6 0.6 1.0"/>
				<texture filename=""/>
			</material>
		</visual>
		<collision>
			<origin xyz="0.0 0.0 0.0" rpy="0.0 0.0 0.0"/>
			<geometry>
				<sphere radius="0.05"/>
			</geometry>
		</collision>
	</link>

	<link name="link_2_y">
		<inertial>
			<origin xyz="0.0 0.0 0.0" rpy="0.0 0.0 0.0"/>
			<mass value="0.00001"/>
			<inertia ixx="0.0000001" ixy="0.0" ixz="0.0" iyy="0.0000001" iyz="0.0" izz="0.0000001"/>
		</inertial>
		<visual name="">
			<origin xyz="0.0 0.0 0.0" rpy="0.0 0.0 0.0"/>
			<geometry>
				<sphere radius="0.05"/>
			</geometry>
			<material name="">
				<color rgba="0.6 0.6 0.6 1.0"/>
				<texture filename=""/>
			</material>
		</visual>
		<collision>
			<origin xyz="0.0 0.0 0.0" rpy="0.0 0.0 0.0"/>
			<geometry>
				<sphere radius="0.05"/>
			</geometry>
		</collision>
	</link>

	<link name="link_2">
		<inertial>
			<origin xyz="0.0 0.0 -0.025" rpy="0.0 0.0 0.0"/>
			<mass value="0.1"/>
			<inertia ixx="0.0" ixy="0.0" ixz="0.0" iyy="0.0" iyz="0.0" izz="0.0"/>
		</inertial>
		<visual name="">
			<origin xyz="0.0 0.0 -0.025" rpy="0.0 0.0 0.0"/>
			<geometry>
				<cylinder radius="0.05" length="0.05"/>
			</geometry>
			<material name="">
				<color rgba="0.6 0.6 0.6 1.0"/>
				<texture filename=""/>
			</material>
		</visual>
		<collision>
			<origin xyz="0.0 0.0 -0.025" rpy="0.0 0.0 0.0"/>
			<geometry>
				<cylinder radius="0.05" length="0.05"/>
			</geometry>
		</collision>
	</link>

	<link name="link_3_x">
		<inertial>
			<origin xyz="0.0 0.0 0.0" rpy="0.0 0.0 0.0"/>
			<mass value="0.00001"/>
			<inertia ixx="0.0000001" ixy="0.0" ixz="0.0" iyy="0.0000001" iyz="0.0" izz="0.0000001"/>
		</inertial>
		<visual name="">
			<origin xyz="0.0 0.0 0.0" rpy="0.0 0.0 0.0"/>
			<geometry>
				<sphere radius="0.05"/>
			</geometry>
			<material name="">
				<color rgba="0.6 0.6 0.6 1.0"/>
				<texture filename=""/>
			</material>
		</visual>
		<collision>
			<origin xyz="0.0 0.0 0.0" rpy="0.0 0.0 0.0"/>
			<geometry>
				<sphere radius="0.05"/>
			</geometry>
		</collision>
	</link>

	<link name="link_3_y">
		<inertial>
			<origin xyz="0.0 0.0 0.0" rpy="0.0 0.0 0.0"/>
			<mass value="0.00001"/>
			<inertia ixx="0.0000001" ixy="0.0" ixz="0.0" iyy="0.0000001" iyz="0.0" izz="0.0000001"/>
		</inertial>
		<visual name="">
			<origin xyz="0.0 0.0 0.0" rpy="0.0 0.0 0.0"/>
			<geometry>
				<sphere radius="0.05"/>
			</geometry>
			<material name="">
				<color rgba="0.6 0.6 0.6 1.0"/>
				<texture filename=""/>
			</material>
		</visual>
		<collision>
			<origin xyz="0.0 0.0 0.0" rpy="0.0 0.0 0.0"/>
			<geometry>
				<sphere radius="0.05"/>
			</geometry>
		</collision>
	</link>

	<link name="link_3">
		<inertial>
			<origin xyz="0.0 0.0 -0.025" rpy="0.0 0.0 0.0"/>
			<mass value="0.1"/>
			<inertia ixx="0.0" ixy="0.0" ixz="0.0" iyy="0.0" iyz="0.0" izz="0.0"/>
		</inertial>
		<visual name="">
			<origin xyz="0.0 0.0 -0.025" rpy="0.0 0.0 0.0"/>
			<geometry>
				<cylinder radius="0.05" length="0.05"/>
			</geometry>
			<material name="">
				<color rgba="0.6 0.6 0.6 1.0"/>
				<texture filename=""/>
			</material>
		</visual>
		<collision>
			<origin xyz="0.0 0.0 -0.025" rpy="0.0 0.0 0.0"/>
			<geometry>
				<cylinder radius="0.05" length="0.05"/>
			</geometry>
		</collision>
	</link>

	<link name="link_4_x">
		<inertial>
			<origin xyz="0.0 0.0 0.0" rpy="0.0 0.0 0.0"/>
			<mass value="0.00001"/>
			<inertia ixx="0.0000001" ixy="0.0" ixz="0.0" iyy="0.0000001" iyz="0.0" izz="0.0000001"/>
		</inertial>
		<visual name="">
			<origin xyz="0.0 0.0 0.0" rpy="0.0 0.0 0.0"/>
			<geometry>
				<sphere radius="0.05"/>
			</geometry>
			<material name="">
				<color rgba="0.6 0.6 0.6 1.0"/>
				<texture filename=""/>
			</material>
		</visual>
		<collision>
			<origin xyz="0.0 0.0 0.0" rpy="0.0 0.0 0.0"/>
			<geometry>
				<sphere radius="0.05"/>
			</geometry>
		</collision>
	</link>

	<link name="link_4_y">
		<inertial>
			<origin xyz="0.0 0.0 0.0" rpy="0.0 0.0 0.0"/>
			<mass value="0.00001"/>
			<inertia ixx="0.0000001" ixy="0.0" ixz="0.0" iyy="0.0000001" iyz="0.0" izz="0.0000001"/>
		</inertial>
		<visual name="">
			<origin xyz="0.0 0.0 0.0" rpy="0.0 0.0 0.0"/>
			<geometry>
				<sphere radius="0.05"/>
			</geometry>
			<material name="">
				<color rgba="0.6 0.6 0.6 1.0"/>
				<texture filename=""/>
			</material>
		</visual>
		<collision>
			<origin xyz="0.0 0.0 0.0" rpy="0.0 0.0 0.0"/>
			<geometry>
				<sphere radius="0.05"/>
			</geometry>
		</collision>
	</link>

	<link name="link_4">
		<inertial>
			<origin xyz="0.0 0.0 -0.025" rpy="0.0 0.0 0.0"/>
			<mass value="0.1"/>
			<inertia ixx="0.0" ixy="0.0" ixz="0.0" iyy="0.0" iyz="0.0" izz="0.0"/>
		</inertial>
		<visual name="">
			<origin xyz="0.0 0.0 -0.025" rpy="0.0 0.0 0.0"/>
			<geometry>
				<cylinder radius="0.05" length="0.05"/>
			</geometry>
			<material name="">
				<color rgba="0.6 0.6 0.6 1.0"/>
				<texture filename=""/>
			</material>
		</visual>
		<collision>
			<origin xyz="0.0 0.0 -0.025" rpy="0.0 0.0 0.0"/>
			<geometry>
				<cylinder radius="0.05" length="0.05"/>
			</geometry>
		</collision>
	</link>

	<link name="link_5_x">
		<inertial>
			<origin xyz="0.0 0.0 0.0" rpy="0.0 0.0 0.0"/>
			<mass value="0.00001"/>
			<inertia ixx="0.0000001" ixy="0.0" ixz="0.0" iyy="0.0000001" iyz="0.0" izz="0.0000001"/>
		</inertial>
		<visual name="">
			<origin xyz="0.0 0.0 0.0" rpy="0.0 0.0 0.0"/>
			<geometry>
				<sphere radius="0.05"/>
			</geometry>
			<material name="">
				<color rgba="0.6 0.6 0.6 1.0"/>
				<texture filename=""/>
			</material>
		</visual>
		<collision>
			<origin xyz="0.0 0.0 0.0" rpy="0.0 0.0 0.0"/>
			<geometry>
				<sphere radius="0.05"/>
			</geometry>
		</collision>
	</link>

	<link name="link_5_y">
		<inertial>
			<origin xyz="0.0 0.0 0.0" rpy="0.0 0.0 0.0"/>
			<mass value="0.00001"/>
			<inertia ixx="0.0000001" ixy="0.0" ixz="0.0" iyy="0.0000001" iyz="0.0" izz="0.0000001"/>
		</inertial>
		<visual name="">
			<origin xyz="0.0 0.0 0.0" rpy="0.0 0.0 0.0"/>
			<geometry>
				<sphere radius="0.05"/>
			</geometry>
			<material name="">
				<color rgba="0.6 0.6 0.6 1.0"/>
				<texture filename=""/>
			</material>
		</visual>
		<collision>
			<origin xyz="0.0 0.0 0.0" rpy="0.0 0.0 0.0"/>
			<geometry>
				<sphere radius="0.05"/>
			</geometry>
		</collision>
	</link>

	<link name="link_5">
		<inertial>
			<origin xyz="0.0 0.0 -0.025" rpy="0.0 0.0 0.0"/>
			<mass value="0.1"/>
			<inertia ixx="0.0" ixy="0.0" ixz="0.0" iyy="0.0" iyz="0.0" izz="0.0"/>
		</inertial>
		<visual name="">
			<origin xyz="0.0 0.0 -0.025" rpy="0.0 0.0 0.0"/>
			<geometry>
				<cylinder radius="0.05" length="0.05"/>
			</geometry>
			<material name="">
				<color rgba="0.6 0.6 0.6 1.0"/>
				<texture filename=""/>
			</material>
		</visual>
		<collision>
			<origin xyz="0.0 0.0 -0.025" rpy="0.0 0.0 0.0"/>
			<geometry>
				<cylinder radius="0.05" length="0.05"/>
			</geometry>
		</collision>
	</link>

	<link name="link_6_x">
		<inertial>
			<origin xyz="0.0 0.0 0.0" rpy="0.0 0.0 0.0"/>
			<mass value="0.00001"/>
			<inertia ixx="0.0000001" ixy="0.0" ixz="0.0" iyy="0.0000001" iyz="0.0" izz="0.0000001"/>
		</inertial>
		<visual name="">
			<origin xyz="0.0 0.0 0.0" rpy="0.0 0.0 0.0"/>
			<geometry>
				<sphere radius="0.05"/>
			</geometry>
			<material name="">
				<color rgba="0.6 0.6 0.6 1.0"/>
				<texture filename=""/>
			</material>
		</visual>
		<collision>
			<origin xyz="0.0 0.0 0.0" rpy="0.0 0.0 0.0"/>
			<geometry>
				<sphere radius="0.05"/>
			</geometry>
		</collision>
	</link>

	<link name="link_6_y">
		<inertial>
			<origin xyz="0.0 0.0 0.0" rpy="0.0 0.0 0.0"/>
			<mass value="0.00001"/>
			<inertia ixx="0.0000001" ixy="0.0" ixz="0.0" iyy="0.0000001" iyz="0.0" izz="0.0000001"/>
		</inertial>
		<visual name="">
			<origin xyz="0.0 0.0 0.0" rpy="0.0 0.0 0.0"/>
			<geometry>
				<sphere radius="0.05"/>
			</geometry>
			<material name="">
				<color rgba="0.6 0.6 0.6 1.0"/>
				<texture filename=""/>
			</material>
		</visual>
		<collision>
			<origin xyz="0.0 0.0 0.0" rpy="0.0 0.0 0.0"/>
			<geometry>
				<sphere radius="0.05"/>
			</geometry>
		</collision>
	</link>

	<link name="link_6">
		<inertial>
			<origin xyz="0.0 0.0 -0.025" rpy="0.0 0.0 0.0"/>
			<mass value="0.1"/>
			<inertia ixx="0.0" ixy="0.0" ixz="0.0" iyy="0.0" iyz="0.0" izz="0.0"/>
		</inertial>
		<visual name="">
			<origin xyz="0.0 0.0 -0.025" rpy="0.0 0.0 0.0"/>
			<geometry>
				<cylinder radius="0.05" length="0.05"/>
			</geometry>
			<material name="">
				<color rgba="0.6 0.6 0.6 1.0"/>
				<texture filename=""/>
			</material>
		</visual>
		<collision>
			<origin xyz="0.0 0.0 -0.025" rpy="0.0 0.0 0.0"/>
			<geometry>
				<cylinder radius="0.05" length="0.05"/>
			</geometry>
		</collision>
	</link>

	<link name="link_7_x">
		<inertial>
			<origin xyz="0.0 0.0 0.0" rpy="0.0 0.0 0.0"/>
			<mass value="0.00001"/>
			<inertia ixx="0.0000001" ixy="0.0" ixz="0.0" iyy="0.0000001" iyz="0.0" izz="0.0000001"/>
		</inertial>
		<visual name="">
			<origin xyz="0.0 0.0 0.0" rpy="0.0 0.0 0.0"/>
			<geometry>
				<sphere radius="0.05"/>
			</geometry>
			<material name="">
				<color rgba="0.6 0.6 0.6 1.0"/>
				<texture filename=""/>
			</material>
		</visual>
		<collision>
			<origin xyz="0.0 0.0 0.0" rpy="0.0 0.0 0.0"/>
			<geometry>
				<sphere radius="0.05"/>
			</geometry>
		</collision>
	</link>

	<link name="link_7_y">
		<inertial>
			<origin xyz="0.0 0.0 0.0" rpy="0.0 0.0 0.0"/>
			<mass value="0.00001"/>
			<inertia ixx="0.0000001" ixy="0.0" ixz="0.0" iyy="0.0000001" iyz="0.0" izz="0.0000001"/>
		</inertial>
		<visual name="">
			<origin xyz="0.0 0.0 0.0" rpy="0.0 0.0 0.0"/>
			<geometry>
				<sphere radius="0.05"/>
			</geometry>
			<material name="">
				<color rgba="0.6 0.6 0.6 1.0"/>
				<texture filename=""/>
			</material>
		</visual>
		<collision>
			<origin xyz="0.0 0.0 0.0" rpy="0.0 0.0 0.0"/>
			<geometry>
				<sphere radius="0.05"/>
			</geometry>
		</collision>
	</link>

	<link name="link_7">
		<inertial>
			<origin xyz="0.0 0.0 -0.025" rpy="0.0 0.0 0.0"/>
			<mass value="0.1"/>
			<inertia ixx="0.0" ixy="0.0" ixz="0.0" iyy="0.0" iyz="0.0" izz="0.0"/>
		</inertial>
		<visual name="">
			<origin xyz="0.0 0.0 -0.025" rpy="0.0 0.0 0.0"/>
			<geometry>
				<cylinder radius="0.05" length="0.05"/>
			</geometry>
			<material name="">
				<color rgba="0.6 0.6 0.6 1.0"/>
				<texture filename=""/>
			</material>
		</visual>
		<collision>
			<origin xyz="0.0 0.0 -0.025" rpy="0.0 0.0 0.0"/>
			<geometry>
				<cylinder radius="0.05" length="0.05"/>
			</geometry>
		</collision>
	</link>

	<link name="link_8_x">
		<inertial>
			<origin xyz="0.0 0.0 0.0" rpy="0.0 0.0 0.0"/>
			<mass value="0.00001"/>
			<inertia ixx="0.0000001" ixy="0.0" ixz="0.0" iyy="0.0000001" iyz="0.0" izz="0.0000001"/>
		</inertial>
		<visual name="">
			<origin xyz="0.0 0.0 0.0" rpy="0.0 0.0 0.0"/>
			<geometry>
				<sphere radius="0.05"/>
			</geometry>
			<material name="">
				<color rgba="0.6 0.6 0.6 1.0"/>
				<texture filename=""/>
			</material>
		</visual>
		<collision>
			<origin xyz="0.0 0.0 0.0" rpy="0.0 0.0 0.0"/>
			<geometry>
				<sphere radius="0.05"/>
			</geometry>
		</collision>
	</link>

	<link name="link_8_y">
		<inertial>
			<origin xyz="0.0 0.0 0.0" rpy="0.0 0.0 0.0"/>
			<mass value="0.00001"/>
			<inertia ixx="0.0000001" ixy="0.0" ixz="0.0" iyy="0.0000001" iyz="0.0" izz="0.0000001"/>
		</inertial>
		<visual name="">
			<origin xyz="0.0 0.0 0.0" rpy="0.0 0.0 0.0"/>
			<geometry>
				<sphere radius="0.05"/>
			</geometry>
			<material name="">
				<color rgba="0.6 0.6 0.6 1.0"/>
				<texture filename=""/>
			</material>
		</visual>
		<collision>
			<origin xyz="0.0 0.0 0.0" rpy="0.0 0.0 0.0"/>
			<geometry>
				<sphere radius="0.05"/>
			</geometry>
		</collision>
	</link>

	<link name="link_8">
		<inertial>
			<origin xyz="0.0 0.0 -0.025" rpy="0.0 0.0 0.0"/>
			<mass value="0.1"/>
			<inertia ixx="0.0" ixy="0.0" ixz="0.0" iyy="0.0" iyz="0.0" izz="0.0"/>
		</inertial>
		<visual name="">
			<origin xyz="0.0 0.0 -0.025" rpy="0.0 0.0 0.0"/>
			<geometry>
				<cylinder radius="0.05" length="0.05"/>
			</geometry>
			<material name="">
				<color rgba="0.6 0.6 0.6 1.0"/>
				<texture filename=""/>
			</material>
		</visual>
		<collision>
			<origin xyz="0.0 0.0 -0.025" rpy="0.0 0.0 0.0"/>
			<geometry>
				<cylinder radius="0.05" length="0.05"/>
			</geometry>
		</collision>
	</link>

	<link name="link_9_x">
		<inertial>
			<origin xyz="0.0 0.0 0.0" rpy="0.0 0.0 0.0"/>
			<mass value="0.00001"/>
			<inertia ixx="0.0000001" ixy="0.0" ixz="0.0" iyy="0.0000001" iyz="0.0" izz="0.0000001"/>
		</inertial>
		<visual name="">
			<origin xyz="0.0 0.0 0.0" rpy="0.0 0.0 0.0"/>
			<geometry>
				<sphere radius="0.05"/>
			</geometry>
			<material name="">
				<color rgba="0.6 0.6 0.6 1.0"/>
				<texture filename=""/>
			</material>
		</visual>
		<collision>
			<origin xyz="0.0 0.0 0.0" rpy="0.0 0.0 0.0"/>
			<geometry>
				<sphere radius="0.05"/>
			</geometry>
		</collision>
	</link>

	<link name="link_9_y">
		<inertial>
			<origin xyz="0.0 0.0 0.0" rpy="0.0 0.0 0.0"/>
			<mass value="0.00001"/>
			<inertia ixx="0.0000001" ixy="0.0" ixz="0.0" iyy="0.0000001" iyz="0.0" izz="0.0000001"/>
		</inertial>
		<visual name="">
			<origin xyz="0.0 0.0 0.0" rpy="0.0 0.0 0.0"/>
			<geometry>
				<sphere radius="0.05"/>
			</geometry>
			<material name="">
				<color rgba="0.6 0.6 0.6 1.0"/>
				<texture filename=""/>
			</material>
		</visual>
		<collision>
			<origin xyz="0.0 0.0 0.0" rpy="0.0 0.0 0.0"/>
			<geometry>
				<sphere radius="0.05"/>
			</geometry>
		</collision>
	</link>

	<link name="link_9">
		<inertial>
			<origin xyz="0.0 0.0 -0.025" rpy="0.0 0.0 0.0"/>
			<mass value="0.1"/>
			<inertia ixx="0.0" ixy="0.0" ixz="0.0" iyy="0.0" iyz="0.0" izz="0.0"/>
		</inertial>
		<visual name="">
			<origin xyz="0.0 0.0 -0.025" rpy="0.0 0.0 0.0"/>
			<geometry>
				<cylinder radius="0.05" length="0.05"/>
			</geometry>
			<material name="">
				<color rgba="0.6 0.6 0.6 1.0"/>
				<texture filename=""/>
			</material>
		</visual>
		<collision>
			<origin xyz="0.0 0.0 -0.025" rpy="0.0 0.0 0.0"/>
			<geometry>
				<cylinder radius="0.05" length="0.05"/>
			</geometry>
		</collision>
	</link>

	<link name="link_10_x">
		<inertial>
			<origin xyz="0.0 0.0 0.0" rpy="0.0 0.0 0.0"/>
			<mass value="0.00001"/>
			<inertia ixx="0.0000001" ixy="0.0" ixz="0.0" iyy="0.0000001" iyz="0.0" izz="0.0000001"/>
		</inertial>
		<visual name="">
			<origin xyz="0.0 0.0 0.0" rpy="0.0 0.0 0.0"/>
			<geometry>
				<sphere radius="0.05"/>
			</geometry>
			<material name="">
				<color rgba="0.6 0.6 0.6 1.0"/>
				<texture filename=""/>
			</material>
		</visual>
		<collision>
			<origin xyz="0.0 0.0 0.0" rpy="0.0 0.0 0.0"/>
			<geometry>
				<sphere radius="0.05"/>
			</geometry>
		</collision>
	</link>

	<link name="link_10_y">
		<inertial>
			<origin xyz="0.0 0.0 0.0" rpy="0.0 0.0 0.0"/>
			<mass value="0.00001"/>
			<inertia ixx="0.0000001" ixy="0.0" ixz="0.0" iyy="0.0000001" iyz="0.0" izz="0.0000001"/>
		</inertial>
		<visual name="">
			<origin xyz="0.0 0.0 0.0" rpy="0.0 0.0 0.0"/>
			<geometry>
				<sphere radius="0.05"/>
			</geometry>
			<material name="">
				<color rgba="0.6 0.6 0.6 1.0"/>
				<texture filename=""/>
			</material>
		</visual>
		<collision>
			<origin xyz="0.0 0.0 0.0" rpy="0.0 0.0 0.0"/>
			<geometry>
				<sphere radius="0.05"/>
			</geometry>
		</collision>
	</link>

	<link name="link_10">
		<inertial>
			<origin xyz="0.0 0.0 -0.025" rpy="0.0 0.0 0.0"/>
			<mass value="0.1"/>
			<inertia ixx="0.0" ixy="0.0" ixz="0.0" iyy="0.0" iyz="0.0" izz="0.0"/>
		</inertial>
		<visual name="">
			<origin xyz="0.0 0.0 -0.025" rpy="0.0 0.0 0.0"/>
			<geometry>
				<cylinder radius="0.05" length="0.05"/>
			</geometry>
			<material name="">
				<color rgba="0.6 0.6 0.6 1.0"/>
				<texture filename=""/>
			</material>
		</visual>
		<collision>
			<origin xyz="0.0 0.0 -0.025" rpy="0.0 0.0 0.0"/>
			<geometry>
				<cylinder radius="0.05" length="0.05"/>
			</geometry>
		</collision>
	</link>

	<link name="link_11_x">
		<inertial>
			<origin xyz="0.0 0.0 0.0" rpy="0.0 0.0 0.0"/>
			<mass value="0.00001"/>
			<inertia ixx="0.0000001" ixy="0.0" ixz="0.0" iyy="0.0000001" iyz="0.0" izz="0.0000001"/>
		</inertial>
		<visual name="">
			<origin xyz="0.0 0.0 0.0" rpy="0.0 0.0 0.0"/>
			<geometry>
				<sphere radius="0.05"/>
			</geometry>
			<material name="">
				<color rgba="0.6 0.6 0.6 1.0"/>
				<texture filename=""/>
			</material>
		</visual>
		<collision>
			<origin xyz="0.0 0.0 0.0" rpy="0.0 0.0 0.0"/>
			<geometry>
				<sphere radius="0.05"/>
			</geometry>
		</collision>
	</link>

	<link name="link_11_y">
		<inertial>
			<origin xyz="0.0 0.0 0.0" rpy="0.0 0.0 0.0"/>
			<mass value="0.00001"/>
			<inertia ixx="0.0000001" ixy="0.0" ixz="0.0" iyy="0.0000001" iyz="0.0" izz="0.0000001"/>
		</inertial>
		<visual name="">
			<origin xyz="0.0 0.0 0.0" rpy="0.0 0.0 0.0"/>
			<geometry>
				<sphere radius="0.05"/>
			</geometry>
			<material name="">
				<color rgba="0.6 0.6 0.6 1.0"/>
				<texture filename=""/>
			</material>
		</visual>
		<collision>
			<origin xyz="0.0 0.0 0.0" rpy="0.0 0.0 0.0"/>
			<geometry>
				<sphere radius="0.05"/>
			</geometry>
		</collision>
	</link>

	<link name="link_11">
		<inertial>
			<origin xyz="0.0 0.0 -0.025" rpy="0.0 0.0 0.0"/>
			<mass value="0.1"/>
			<inertia ixx="0.0" ixy="0.0" ixz="0.0" iyy="0.0" iyz="0.0" izz="0.0"/>
		</inertial>
		<visual name="">
			<origin xyz="0.0 0.0 -0.025" rpy="0.0 0.0 0.0"/>
			<geometry>
				<cylinder radius="0.05" length="0.05"/>
			</geometry>
			<material name="">
				<color rgba="0.6 0.6 0.6 1.0"/>
				<texture filename=""/>
			</material>
		</visual>
		<collision>
			<origin xyz="0.0 0.0 -0.025" rpy="0.0 0.0 0.0"/>
			<geometry>
				<cylinder radius="0.05" length="0.05"/>
			</geometry>
		</collision>
	</link>

	<link name="link_12_x">
		<inertial>
			<origin xyz="0.0 0.0 0.0" rpy="0.0 0.0 0.0"/>
			<mass value="0.00001"/>
			<inertia ixx="0.0000001" ixy="0.0" ixz="0.0" iyy="0.0000001" iyz="0.0" izz="0.0000001"/>
		</inertial>
		<visual name="">
			<origin xyz="0.0 0.0 0.0" rpy="0.0 0.0 0.0"/>
			<geometry>
				<sphere radius="0.05"/>
			</geometry>
			<material name="">
				<color rgba="0.6 0.6 0.6 1.0"/>
				<texture filename=""/>
			</material>
		</visual>
		<collision>
			<origin xyz="0.0 0.0 0.0" rpy="0.0 0.0 0.0"/>
			<geometry>
				<sphere radius="0.05"/>
			</geometry>
		</collision>
	</link>

	<link name="link_12_y">
		<inertial>
			<origin xyz="0.0 0.0 0.0" rpy="0.0 0.0 0.0"/>
			<mass value="0.00001"/>
			<inertia ixx="0.0000001" ixy="0.0" ixz="0.0" iyy="0.0000001" iyz="0.0" izz="0.0000001"/>
		</inertial>
		<visual name="">
			<origin xyz="0.0 0.0 0.0" rpy="0.0 0.0 0.0"/>
			<geometry>
				<sphere radius="0.05"/>
			</geometry>
			<material name="">
				<color rgba="0.6 0.6 0.6 1.0"/>
				<texture filename=""/>
			</material>
		</visual>
		<collision>
			<origin xyz="0.0 0.0 0.0" rpy="0.0 0.0 0.0"/>
			<geometry>
				<sphere radius="0.05"/>
			</geometry>
		</collision>
	</link>

	<link name="link_12">
		<inertial>
			<origin xyz="0.0 0.0 -0.025" rpy="0.0 0.0 0.0"/>
			<mass value="0.1"/>
			<inertia ixx="0.0" ixy="0.0" ixz="0.0" iyy="0.0" iyz="0.0" izz="0.0"/>
		</inertial>
		<visual name="">
			<origin xyz="0.0 0.0 -0.025" rpy="0.0 0.0 0.0"/>
			<geometry>
				<cylinder radius="0.05" length="0.05"/>
			</geometry>
			<material name="">
				<color rgba="0.6 0.6 0.6 1.0"/>
				<texture filename=""/>
			</material>
		</visual>
		<collision>
			<origin xyz="0.0 0.0 -0.025" rpy="0.0 0.0 0.0"/>
			<geometry>
				<cylinder radius="0.05" length="0.05"/>
			</geometry>
		</collision>
	</link>

	<link name="link_13_x">
		<inertial>
			<origin xyz="0.0 0.0 0.0" rpy="0.0 0.0 0.0"/>
			<mass value="0.00001"/>
			<inertia ixx="0.0000001" ixy="0.0" ixz="0.0" iyy="0.0000001" iyz="0.0" izz="0.0000001"/>
		</inertial>
		<visual name="">
			<origin xyz="0.0 0.0 0.0" rpy="0.0 0.0 0.0"/>
			<geometry>
				<sphere radius="0.05"/>
			</geometry>
			<material name="">
				<color rgba="0.6 0.6 0.6 1.0"/>
				<texture filename=""/>
			</material>
		</visual>
		<collision>
			<origin xyz="0.0 0.0 0.0" rpy="0.0 0.0 0.0"/>
			<geometry>
				<sphere radius="0.05"/>
			</geometry>
		</collision>
	</link>

	<link name="link_13_y">
		<inertial>
			<origin xyz="0.0 0.0 0.0" rpy="0.0 0.0 0.0"/>
			<mass value="0.00001"/>
			<inertia ixx="0.0000001" ixy="0.0" ixz="0.0" iyy="0.0000001" iyz="0.0" izz="0.0000001"/>
		</inertial>
		<visual name="">
			<origin xyz="0.0 0.0 0.0" rpy="0.0 0.0 0.0"/>
			<geometry>
				<sphere radius="0.05"/>
			</geometry>
			<material name="">
				<color rgba="0.6 0.6 0.6 1.0"/>
				<texture filename=""/>
			</material>
		</visual>
		<collision>
			<origin xyz="0.0 0.0 0.0" rpy="0.0 0.0 0.0"/>
			<geometry>
				<sphere radius="0.05"/>
			</geometry>
		</collision>
	</link>

	<link name="link_13">
		<inertial>
			<origin xyz="0.0 0.0 -0.025" rpy="0.0 0.0 0.0"/>
			<mass value="0.1"/>
			<inertia ixx="0.0" ixy="0.0" ixz="0.0" iyy="0.0" iyz="0.0" izz="0.0"/>
		</inertial>
		<visual name="">
			<origin xyz="0.0 0.0 -0.025" rpy="0.0 0.0 0.0"/>
			<geometry>
				<cylinder radius="0.05" length="0.05"/>
			</geometry>
			<material name="">
				<color rgba="0.6 0.6 0.6 1.0"/>
				<texture filename=""/>
			</material>
		</visual>
		<collision>
			<origin xyz="0.0 0.0 -0.025" rpy="0.0 0.0 0.0"/>
			<geometry>
				<cylinder radius="0.05" length="0.05"/>
			</geometry>
		</collision>
	</link>

	<link name="link_14_x">
		<inertial>
			<origin xyz="0.0 0.0 0.0" rpy="0.0 0.0 0.0"/>
			<mass value="0.00001"/>
			<inertia ixx="0.0000001" ixy="0.0" ixz="0.0" iyy="0.0000001" iyz="0.0" izz="0.0000001"/>
		</inertial>
		<visual name="">
			<origin xyz="0.0 0.0 0.0" rpy="0.0 0.0 0.0"/>
			<geometry>
				<sphere radius="0.05"/>
			</geometry>
			<material name="">
				<color rgba="0.6 0.6 0.6 1.0"/>
				<texture filename=""/>
			</material>
		</visual>
		<collision>
			<origin xyz="0.0 0.0 0.0" rpy="0.0 0.0 0.0"/>
			<geometry>
				<sphere radius="0.05"/>
			</geometry>
		</collision>
	</link>

	<link name="link_14_y">
		<inertial>
			<origin xyz="0.0 0.0 0.0" rpy="0.0 0.0 0.0"/>
			<mass value="0.00001"/>
			<inertia ixx="0.0000001" ixy="0.0" ixz="0.0" iyy="0.0000001" iyz="0.0" izz="0.0000001"/>
		</inertial>
		<visual name="">
			<origin xyz="0.0 0.0 0.0" rpy="0.0 0.0 0.0"/>
			<geometry>
				<sphere radius="0.05"/>
			</geometry>
			<material name="">
				<color rgba="0.6 0.6 0.6 1.0"/>
				<texture filename=""/>
			</material>
		</visual>
		<collision>
			<origin xyz="0.0 0.0 0.0" rpy="0.0 0.0 0.0"/>
			<geometry>
				<sphere radius="0.05"/>
			</geometry>
		</collision>
	</link>

	<link name="link_14">
		<inertial>
			<origin xyz="0.0 0.0 -0.025" rpy="0.0 0.0 0.0"/>
			<mass value="0.1"/>
			<inertia ixx="0.0" ixy="0.0" ixz="0.0" iyy="0.0" iyz="0.0" izz="0.0"/>
		</inertial>
		<visual name="">
			<origin xyz="0.0 0.0 -0.025" rpy="0.0 0.0 0.0"/>
			<geometry>
				<cylinder radius="0.05" length="0.05"/>
			</geometry>
			<material name="">
				<color rgba="0.6 0.6 0.6 1.0"/>
				<texture filename=""/>
			</material>
		</visual>
		<collision>
			<origin xyz="0.0 0.0 -0.025" rpy="0.0 0.0 0.0"/>
			<geometry>
				<cylinder radius="0.05" length="0.05"/>
			</geometry>
		</collision>
	</link>

	<link name="link_15_x">
		<inertial>
			<origin xyz="0.0 0.0 0.0" rpy="0.0 0.0 0.0"/>
			<mass value="0.00001"/>
			<inertia ixx="0.0000001" ixy="0.0" ixz="0.0" iyy="0.0000001" iyz="0.0" izz="0.0000001"/>
		</inertial>
		<visual name="">
			<origin xyz="0.0 0.0 0.0" rpy="0.0 0.0 0.0"/>
			<geometry>
				<sphere radius="0.05"/>
			</geometry>
			<material name="">
				<color rgba="0.6 0.6 0.6 1.0"/>
				<texture filename=""/>
			</material>
		</visual>
		<collision>
			<origin xyz="0.0 0.0 0.0" rpy="0.0 0.0 0.0"/>
			<geometry>
				<sphere radius="0.05"/>
			</geometry>
		</collision>
	</link>

	<link name="link_15_y">
		<inertial>
			<origin xyz="0.0 0.0 0.0" rpy="0.0 0.0 0.0"/>
			<mass value="0.00001"/>
			<inertia ixx="0.0000001" ixy="0.0" ixz="0.0" iyy="0.0000001" iyz="0.0" izz="0.0000001"/>
		</inertial>
		<visual name="">
			<origin xyz="0.0 0.0 0.0" rpy="0.0 0.0 0.0"/>
			<geometry>
				<sphere radius="0.05"/>
			</geometry>
			<material name="">
				<color rgba="0.6 0.6 0.6 1.0"/>
				<texture filename=""/>
			</material>
		</visual>
		<collision>
			<origin xyz="0.0 0.0 0.0" rpy="0.0 0.0 0.0"/>
			<geometry>
				<sphere radius="0.05"/>
			</geometry>
		</collision>
	</link>

	<link name="link_15">
		<inertial>
			<origin xyz="0.0 0.0 -0.025" rpy="0.0 0.0 0.0"/>
			<mass value="0.1"/>
			<inertia ixx="0.0" ixy="0.0" ixz="0.0" iyy="0.0" iyz="0.0" izz="0.0"/>
		</inertial>
		<visual name="">
			<origin xyz="0.0 0.0 -0.025" rpy="0.0 0.0 0.0"/>
			<geometry>
				<cylinder radius="0.05" length="0.05"/>
			</geometry>
			<material name="">
				<color rgba="0.6 0.6 0.6 1.0"/>
				<texture filename=""/>
			</material>
		</visual>
		<collision>
			<origin xyz="0.0 0.0 -0.025" rpy="0.0 0.0 0.0"/>
			<geometry>
				<cylinder radius="0.05" length="0.05"/>
			</geometry>
		</collision>
	</link>

	<link name="link_16_x">
		<inertial>
			<origin xyz="0.0 0.0 0.0" rpy="0.0 0.0 0.0"/>
			<mass value="0.00001"/>
			<inertia ixx="0.0000001" ixy="0.0" ixz="0.0" iyy="0.0000001" iyz="0.0" izz="0.0000001"/>
		</inertial>
		<visual name="">
			<origin xyz="0.0 0.0 0.0" rpy="0.0 0.0 0.0"/>
			<geometry>
				<sphere radius="0.05"/>
			</geometry>
			<material name="">
				<color rgba="0.6 0.6 0.6 1.0"/>
				<texture filename=""/>
			</material>
		</visual>
		<collision>
			<origin xyz="0.0 0.0 0.0" rpy="0.0 0.0 0.0"/>
			<geometry>
				<sphere radius="0.05"/>
			</geometry>
		</collision>
	</link>

	<link name="link_16_y">
		<inertial>
			<origin xyz="0.0 0.0 0.0" rpy="0.0 0.0 0.0"/>
			<mass value="0.00001"/>
			<inertia ixx="0.0000001" ixy="0.0" ixz="0.0" iyy="0.0000001" iyz="0.0" izz="0.0000001"/>
		</inertial>
		<visual name="">
			<origin xyz="0.0 0.0 0.0" rpy="0.0 0.0 0.0"/>
			<geometry>
				<sphere radius="0.05"/>
			</geometry>
			<material name="">
				<color rgba="0.6 0.6 0.6 1.0"/>
				<texture filename=""/>
			</material>
		</visual>
		<collision>
			<origin xyz="0.0 0.0 0.0" rpy="0.0 0.0 0.0"/>
			<geometry>
				<sphere radius="0.05"/>
			</geometry>
		</collision>
	</link>

	<link name="link_16">
		<inertial>
			<origin xyz="0.0 0.0 -0.025" rpy="0.0 0.0 0.0"/>
			<mass value="0.1"/>
			<inertia ixx="0.0" ixy="0.0" ixz="0.0" iyy="0.0" iyz="0.0" izz="0.0"/>
		</inertial>
		<visual name="">
			<origin xyz="0.0 0.0 -0.025" rpy="0.0 0.0 0.0"/>
			<geometry>
				<cylinder radius="0.05" length="0.05"/>
			</geometry>
			<material name="">
				<color rgba="0.6 0.6 0.6 1.0"/>
				<texture filename=""/>
			</material>
		</visual>
		<collision>
			<origin xyz="0.0 0.0 -0.025" rpy="0.0 0.0 0.0"/>
			<geometry>
				<cylinder radius="0.05" length="0.05"/>
			</geometry>
		</collision>
	</link>

	<link name="link_17_x">
		<inertial>
			<origin xyz="0.0 0.0 0.0" rpy="0.0 0.0 0.0"/>
			<mass value="0.00001"/>
			<inertia ixx="0.0000001" ixy="0.0" ixz="0.0" iyy="0.0000001" iyz="0.0" izz="0.0000001"/>
		</inertial>
		<visual name="">
			<origin xyz="0.0 0.0 0.0" rpy="0.0 0.0 0.0"/>
			<geometry>
				<sphere radius="0.05"/>
			</geometry>
			<material name="">
				<color rgba="0.6 0.6 0.6 1.0"/>
				<texture filename=""/>
			</material>
		</visual>
		<collision>
			<origin xyz="0.0 0.0 0.0" rpy="0.0 0.0 0.0"/>
			<geometry>
				<sphere radius="0.05"/>
			</geometry>
		</collision>
	</link>

	<link name="link_17_y">
		<inertial>
			<origin xyz="0.0 0.0 0.0" rpy="0.0 0.0 0.0"/>
			<mass value="0.00001"/>
			<inertia ixx="0.0000001" ixy="0.0" ixz="0.0" iyy="0.0000001" iyz="0.0" izz="0.0000001"/>
		</inertial>
		<visual name="">
			<origin xyz="0.0 0.0 0.0" rpy="0.0 0.0 0.0"/>
			<geometry>
				<sphere radius="0.05"/>
			</geometry>
			<material name="">
				<color rgba="0.6 0.6 0.6 1.0"/>
				<texture filename=""/>
			</material>
		</visual>
		<collision>
			<origin xyz="0.0 0.0 0.0" rpy="0.0 0.0 0.0"/>
			<geometry>
				<sphere radius="0.05"/>
			</geometry>
		</collision>
	</link>

	<link name="link_17">
		<inertial>
			<origin xyz="0.0 0.0 -0.025" rpy="0.0 0.0 0.0"/>
			<mass value="0.1"/>
			<inertia ixx="0.0" ixy="0.0" ixz="0.0" iyy="0.0" iyz="0.0" izz="0.0"/>
		</inertial>
		<visual name="">
			<origin xyz="0.0 0.0 -0.025" rpy="0.0 0.0 0.0"/>
			<geometry>
				<cylinder radius="0.05" length="0.05"/>
			</geometry>
			<material name="">
				<color rgba="0.6 0.6 0.6 1.0"/>
				<texture filename=""/>
			</material>
		</visual>
		<collision>
			<origin xyz="0.0 0.0 -0.025" rpy="0.0 0.0 0.0"/>
			<geometry>
				<cylinder radius="0.05" length="0.05"/>
			</geometry>
		</collision>
	</link>

	<link name="link_18_x">
		<inertial>
			<origin xyz="0.0 0.0 0.0" rpy="0.0 0.0 0.0"/>
			<mass value="0.00001"/>
			<inertia ixx="0.0000001" ixy="0.0" ixz="0.0" iyy="0.0000001" iyz="0.0" izz="0.0000001"/>
		</inertial>
		<visual name="">
			<origin xyz="0.0 0.0 0.0" rpy="0.0 0.0 0.0"/>
			<geometry>
				<sphere radius="0.05"/>
			</geometry>
			<material name="">
				<color rgba="0.6 0.6 0.6 1.0"/>
				<texture filename=""/>
			</material>
		</visual>
		<collision>
			<origin xyz="0.0 0.0 0.0" rpy="0.0 0.0 0.0"/>
			<geometry>
				<sphere radius="0.05"/>
			</geometry>
		</collision>
	</link>

	<link name="link_18_y">
		<inertial>
			<origin xyz="0.0 0.0 0.0" rpy="0.0 0.0 0.0"/>
			<mass value="0.00001"/>
			<inertia ixx="0.0000001" ixy="0.0" ixz="0.0" iyy="0.0000001" iyz="0.0" izz="0.0000001"/>
		</inertial>
		<visual name="">
			<origin xyz="0.0 0.0 0.0" rpy="0.0 0.0 0.0"/>
			<geometry>
				<sphere radius="0.05"/>
			</geometry>
			<material name="">
				<color rgba="0.6 0.6 0.6 1.0"/>
				<texture filename=""/>
			</material>
		</visual>
		<collision>
			<origin xyz="0.0 0.0 0.0" rpy="0.0 0.0 0.0"/>
			<geometry>
				<sphere radius="0.05"/>
			</geometry>
		</collision>
	</link>

	<link name="link_18">
		<inertial>
			<origin xyz="0.0 0.0 -0.025" rpy="0.0 0.0 0.0"/>
			<mass value="0.1"/>
			<inertia ixx="0.0" ixy="0.0" ixz="0.0" iyy="0.0" iyz="0.0" izz="0.0"/>
		</inertial>
		<visual name="">
			<origin xyz="0.0 0.0 -0.025" rpy="0.0 0.0 0.0"/>
			<geometry>
				<cylinder radius="0.05" length="0.05"/>
			</geometry>
			<material name="">
				<color rgba="0.6 0.6 0.6 1.0"/>
				<texture filename=""/>
			</material>
		</visual>
		<collision>
			<origin xyz="0.0 0.0 -0.025" rpy="0.0 0.0 0.0"/>
			<geometry>
				<cylinder radius="0.05" length="0.05"/>
			</geometry>
		</collision>
	</link>

	<joint name="joint_0_x" type="revolute">
		<origin xyz="0.0 0.0 -0.05" rpy="0.0 0.0 0.0"/>
		<parent link="link_-1"/>
		<child link="link_0_x"/>
		<axis xyz="1.0 0.0 0.0"/>
		<limit lower="-1.57" upper="1.57" effort="1000" velocity="20"/>
		<dynamics damping="0.005"/>
	</joint>

	<joint name="joint_0_y" type="revolute">
		<origin xyz="0.0 0.0 0.0" rpy="0.0 0.0 0.0"/>
		<parent link="link_0_x"/>
		<child link="link_0_y"/>
		<axis xyz="0.0 1.0 0.0"/>
		<limit lower="-1.57" upper="1.57" effort="1000" velocity="20"/>
		<dynamics damping="0.005"/>
	</joint>

	<joint name="joint_0_z" type="continuous">
		<origin xyz="0.0 0.0 0.0" rpy="0.0 0.0 0.0"/>
		<parent link="link_0_y"/>
		<child link="link_0"/>
		<axis xyz="0.0 0.0 1.0"/>
		<dynamics damping="0.005"/>
	</joint>

	<joint name="joint_1_x" type="revolute">
		<origin xyz="0.0 0.0 -0.05" rpy="0.0 0.0 0.0"/>
		<parent link="link_0"/>
		<child link="link_1_x"/>
		<axis xyz="1.0 0.0 0.0"/>
		<limit lower="-1.57" upper="1.57" effort="1000" velocity="20"/>
		<dynamics damping="0.005"/>
	</joint>

	<joint name="joint_1_y" type="revolute">
		<origin xyz="0.0 0.0 0.0" rpy="0.0 0.0 0.0"/>
		<parent link="link_1_x"/>
		<child link="link_1_y"/>
		<axis xyz="0.0 1.0 0.0"/>
		<limit lower="-1.57" upper="1.57" effort="1000" velocity="20"/>
		<dynamics damping="0.005"/>
	</joint>

	<joint name="joint_1_z" type="continuous">
		<origin xyz="0.0 0.0 0.0" rpy="0.0 0.0 0.0"/>
		<parent link="link_1_y"/>
		<child link="link_1"/>
		<axis xyz="0.0 0.0 1.0"/>
		<dynamics damping="0.005"/>
	</joint>

	<joint name="joint_2_x" type="revolute">
		<origin xyz="0.0 0.0 -0.05" rpy="0.0 0.0 0.0"/>
		<parent link="link_1"/>
		<child link="link_2_x"/>
		<axis xyz="1.0 0.0 0.0"/>
		<limit lower="-1.57" upper="1.57" effort="1000" velocity="20"/>
		<dynamics damping="0.005"/>
	</joint>

	<joint name="joint_2_y" type="revolute">
		<origin xyz="0.0 0.0 0.0" rpy="0.0 0.0 0.0"/>
		<parent link="link_2_x"/>
		<child link="link_2_y"/>
		<axis xyz="0.0 1.0 0.0"/>
		<limit lower="-1.57" upper="1.57" effort="1000" velocity="20"/>
		<dynamics damping="0.005"/>
	</joint>

	<joint name="joint_2_z" type="continuous">
		<origin xyz="0.0 0.0 0.0" rpy="0.0 0.0 0.0"/>
		<parent link="link_2_y"/>
		<child link="link_2"/>
		<axis xyz="0.0 0.0 1.0"/>
		<dynamics damping="0.005"/>
	</joint>

	<joint name="joint_3_x" type="revolute">
		<origin xyz="0.0 0.0 -0.05" rpy="0.0 0.0 0.0"/>
		<parent link="link_2"/>
		<child link="link_3_x"/>
		<axis xyz="1.0 0.0 0.0"/>
		<limit lower="-1.57" upper="1.57" effort="1000" velocity="20"/>
		<dynamics damping="0.005"/>
	</joint>

	<joint name="joint_3_y" type="revolute">
		<origin xyz="0.0 0.0 0.0" rpy="0.0 0.0 0.0"/>
		<parent link="link_3_x"/>
		<child link="link_3_y"/>
		<axis xyz="0.0 1.0 0.0"/>
		<limit lower="-1.57" upper="1.57" effort="1000" velocity="20"/>
		<dynamics damping="0.005"/>
	</joint>

	<joint name="joint_3_z" type="continuous">
		<origin xyz="0.0 0.0 0.0" rpy="0.0 0.0 0.0"/>
		<parent link="link_3_y"/>
		<child link="link_3"/>
		<axis xyz="0.0 0.0 1.0"/>
		<dynamics damping="0.005"/>
	</joint>

	<joint name="joint_4_x" type="revolute">
		<origin xyz="0.0 0.0 -0.05" rpy="0.0 0.0 0.0"/>
		<parent link="link_3"/>
		<child link="link_4_x"/>
		<axis xyz="1.0 0.0 0.0"/>
		<limit lower="-1.57" upper="1.57" effort="1000" velocity="20"/>
		<dynamics damping="0.005"/>
	</joint>

	<joint name="joint_4_y" type="revolute">
		<origin xyz="0.0 0.0 0.0" rpy="0.0 0.0 0.0"/>
		<parent link="link_4_x"/>
		<child link="link_4_y"/>
		<axis xyz="0.0 1.0 0.0"/>
		<limit lower="-1.57" upper="1.57" effort="1000" velocity="20"/>
		<dynamics damping="0.005"/>
	</joint>

	<joint name="joint_4_z" type="continuous">
		<origin xyz="0.0 0.0 0.0" rpy="0.0 0.0 0.0"/>
		<parent link="link_4_y"/>
		<child link="link_4"/>
		<axis xyz="0.0 0.0 1.0"/>
		<dynamics damping="0.005"/>
	</joint>

	<joint name="joint_5_x" type="revolute">
		<origin xyz="0.0 0.0 -0.05" rpy="0.0 0.0 0.0"/>
		<parent link="link_4"/>
		<child link="link_5_x"/>
		<axis xyz="1.0 0.0 0.0"/>
		<limit lower="-1.57" upper="1.57" effort="1000" velocity="20"/>
		<dynamics damping="0.005"/>
	</joint>

	<joint name="joint_5_y" type="revolute">
		<origin xyz="0.0 0.0 0.0" rpy="0.0 0.0 0.0"/>
		<parent link="link_5_x"/>
		<child link="link_5_y"/>
		<axis xyz="0.0 1.0 0.0"/>
		<limit lower="-1.57" upper="1.57" effort="1000" velocity="20"/>
		<dynamics damping="0.005"/>
	</joint>

	<joint name="joint_5_z" type="continuous">
		<origin xyz="0.0 0.0 0.0" rpy="0.0 0.0 0.0"/>
		<parent link="link_5_y"/>
		<child link="link_5"/>
		<axis xyz="0.0 0.0 1.0"/>
		<dynamics damping="0.005"/>
	</joint>

	<joint name="joint_6_x" type="revolute">
		<origin xyz="0.0 0.0 -0.05" rpy="0.0 0.0 0.0"/>
		<parent link="link_5"/>
		<child link="link_6_x"/>
		<axis xyz="1.0 0.0 0.0"/>
		<limit lower="-1.57" upper="1.57" effort="1000" velocity="20"/>
		<dynamics damping="0.005"/>
	</joint>

	<joint name="joint_6_y" type="revolute">
		<origin xyz="0.0 0.0 0.0" rpy="0.0 0.0 0.0"/>
		<parent link="link_6_x"/>
		<child link="link_6_y"/>
		<axis xyz="0.0 1.0 0.0"/>
		<limit lower="-1.57" upper="1.57" effort="1000" velocity="20"/>
		<dynamics damping="0.005"/>
	</joint>

	<joint name="joint_6_z" type="continuous">
		<origin xyz="0.0 0.0 0.0" rpy="0.0 0.0 0.0"/>
		<parent link="link_6_y"/>
		<child link="link_6"/>
		<axis xyz="0.0 0.0 1.0"/>
		<dynamics damping="0.005"/>
	</joint>

	<joint name="joint_7_x" type="revolute">
		<origin xyz="0.0 0.0 -0.05" rpy="0.0 0.0 0.0"/>
		<parent link="link_6"/>
		<child link="link_7_x"/>
		<axis xyz="1.0 0.0 0.0"/>
		<limit lower="-1.57" upper="1.57" effort="1000" velocity="20"/>
		<dynamics damping="0.005"/>
	</joint>

	<joint name="joint_7_y" type="revolute">
		<origin xyz="0.0 0.0 0.0" rpy="0.0 0.0 0.0"/>
		<parent link="link_7_x"/>
		<child link="link_7_y"/>
		<axis xyz="0.0 1.0 0.0"/>
		<limit lower="-1.57" upper="1.57" effort="1000" velocity="20"/>
		<dynamics damping="0.005"/>
	</joint>

	<joint name="joint_7_z" type="continuous">
		<origin xyz="0.0 0.0 0.0" rpy="0.0 0.0 0.0"/>
		<parent link="link_7_y"/>
		<child link="link_7"/>
		<axis xyz="0.0 0.0 1.0"/>
		<dynamics damping="0.005"/>
	</joint>

	<joint name="joint_8_x" type="revolute">
		<origin xyz="0.0 0.0 -0.05" rpy="0.0 0.0 0.0"/>
		<parent link="link_7"/>
		<child link="link_8_x"/>
		<axis xyz="1.0 0.0 0.0"/>
		<limit lower="-1.57" upper="1.57" effort="1000" velocity="20"/>
		<dynamics damping="0.005"/>
	</joint>

	<joint name="joint_8_y" type="revolute">
		<origin xyz="0.0 0.0 0.0" rpy="0.0 0.0 0.0"/>
		<parent link="link_8_x"/>
		<child link="link_8_y"/>
		<axis xyz="0.0 1.0 0.0"/>
		<limit lower="-1.57" upper="1.57" effort="1000" velocity="20"/>
		<dynamics damping="0.005"/>
	</joint>

	<joint name="joint_8_z" type="continuous">
		<origin xyz="0.0 0.0 0.0" rpy="0.0 0.0 0.0"/>
		<parent link="link_8_y"/>
		<child link="link_8"/>
		<axis xyz="0.0 0.0 1.0"/>
		<dynamics damping="0.005"/>
	</joint>

	<joint name="joint_9_x" type="revolute">
		<origin xyz="0.0 0.0 -0.05" rpy="0.0 0.0 0.0"/>
		<parent link="link_8"/>
		<child link="link_9_x"/>
		<axis xyz="1.0 0.0 0.0"/>
		<limit lower="-1.57" upper="1.57" effort="1000" velocity="20"/>
		<dynamics damping="0.005"/>
	</joint>

	<joint name="joint_9_y" type="revolute">
		<origin xyz="0.0 0.0 0.0" rpy="0.0 0.0 0.0"/>
		<parent link="link_9_x"/>
		<child link="link_9_y"/>
		<axis xyz="0.0 1.0 0.0"/>
		<limit lower="-1.57" upper="1.57" effort="1000" velocity="20"/>
		<dynamics damping="0.005"/>
	</joint>

	<joint name="joint_9_z" type="continuous">
		<origin xyz="0.0 0.0 0.0" rpy="0.0 0.0 0.0"/>
		<parent link="link_9_y"/>
		<child link="link_9"/>
		<axis xyz="0.0 0.0 1.0"/>
		<dynamics damping="0.005"/>
	</joint>

	<joint name="joint_10_x" type="revolute">
		<origin xyz="0.0 0.0 -0.05" rpy="0.0 0.0 0.0"/>
		<parent link="link_9"/>
		<child link="link_10_x"/>
		<axis xyz="1.0 0.0 0.0"/>
		<limit lower="-1.57" upper="1.57" effort="1000" velocity="20"/>
		<dynamics damping="0.005"/>
	</joint>

	<joint name="joint_10_y" type="revolute">
		<origin xyz="0.0 0.0 0.0" rpy="0.0 0.0 0.0"/>
		<parent link="link_10_x"/>
		<child link="link_10_y"/>
		<axis xyz="0.0 1.0 0.0"/>
		<limit lower="-1.57" upper="1.57" effort="1000" velocity="20"/>
		<dynamics damping="0.005"/>
	</joint>

	<joint name="joint_10_z" type="continuous">
		<origin xyz="0.0 0.0 0.0" rpy="0.0 0.0 0.0"/>
		<parent link="link_10_y"/>
		<child link="link_10"/>
		<axis xyz="0.0 0.0 1.0"/>
		<dynamics damping="0.005"/>
	</joint>

	<joint name="joint_11_x" type="revolute">
		<origin xyz="0.0 0.0 -0.05" rpy="0.0 0.0 0.0"/>
		<parent link="link_10"/>
		<child link="link_11_x"/>
		<axis xyz="1.0 0.0 0.0"/>
		<limit lower="-1.57" upper="1.57" effort="1000" velocity="20"/>
		<dynamics damping="0.005"/>
	</joint>

	<joint name="joint_11_y" type="revolute">
		<origin xyz="0.0 0.0 0.0" rpy="0.0 0.0 0.0"/>
		<parent link="link_11_x"/>
		<child link="link_11_y"/>
		<axis xyz="0.0 1.0 0.0"/>
		<limit lower="-1.57" upper="1.57" effort="1000" velocity="20"/>
		<dynamics damping="0.005"/>
	</joint>

	<joint name="joint_11_z" type="continuous">
		<origin xyz="0.0 0.0 0.0" rpy="0.0 0.0 0.0"/>
		<parent link="link_11_y"/>
		<child link="link_11"/>
		<axis xyz="0.0 0.0 1.0"/>
		<dynamics damping="0.005"/>
	</joint>

	<joint name="joint_12_x" type="revolute">
		<origin xyz="0.0 0.0 -0.05" rpy="0.0 0.0 0.0"/>
		<parent link="link_11"/>
		<child link="link_12_x"/>
		<axis xyz="1.0 0.0 0.0"/>
		<limit lower="-1.57" upper="1.57" effort="1000" velocity="20"/>
		<dynamics damping="0.005"/>
	</joint>

	<joint name="joint_12_y" type="revolute">
		<origin xyz="0.0 0.0 0.0" rpy="0.0 0.0 0.0"/>
		<parent link="link_12_x"/>
		<child link="link_12_y"/>
		<axis xyz="0.0 1.0 0.0"/>
		<limit lower="-1.57" upper="1.57" effort="1000" velocity="20"/>
		<dynamics damping="0.005"/>
	</joint>

	<joint name="joint_12_z" type="continuous">
		<origin xyz="0.0 0.0 0.0" rpy="0.0 0.0 0.0"/>
		<parent link="link_12_y"/>
		<child link="link_12"/>
		<axis xyz="0.0 0.0 1.0"/>
		<dynamics damping="0.005"/>
	</joint>

	<joint name="joint_13_x" type="revolute">
		<origin xyz="0.0 0.0 -0.05" rpy="0.0 0.0 0.0"/>
		<parent link="link_12"/>
		<child link="link_13_x"/>
		<axis xyz="1.0 0.0 0.0"/>
		<limit lower="-1.57" upper="1.57" effort="1000" velocity="20"/>
		<dynamics damping="0.005"/>
	</joint>

	<joint name="joint_13_y" type="revolute">
		<origin xyz="0.0 0.0 0.0" rpy="0.0 0.0 0.0"/>
		<parent link="link_13_x"/>
		<child link="link_13_y"/>
		<axis xyz="0.0 1.0 0.0"/>
		<limit lower="-1.57" upper="1.57" effort="1000" velocity="20"/>
		<dynamics damping="0.005"/>
	</joint>

	<joint name="joint_13_z" type="continuous">
		<origin xyz="0.0 0.0 0.0" rpy="0.0 0.0 0.0"/>
		<parent link="link_13_y"/>
		<child link="link_13"/>
		<axis xyz="0.0 0.0 1.0"/>
		<dynamics damping="0.005"/>
	</joint>

	<joint name="joint_14_x" type="revolute">
		<origin xyz="0.0 0.0 -0.05" rpy="0.0 0.0 0.0"/>
		<parent link="link_13"/>
		<child link="link_14_x"/>
		<axis xyz="1.0 0.0 0.0"/>
		<limit lower="-1.57" upper="1.57" effort="1000" velocity="20"/>
		<dynamics damping="0.005"/>
	</joint>

	<joint name="joint_14_y" type="revolute">
		<origin xyz="0.0 0.0 0.0" rpy="0.0 0.0 0.0"/>
		<parent link="link_14_x"/>
		<child link="link_14_y"/>
		<axis xyz="0.0 1.0 0.0"/>
		<limit lower="-1.57" upper="1.57" effort="1000" velocity="20"/>
		<dynamics damping="0.005"/>
	</joint>

	<joint name="joint_14_z" type="continuous">
		<origin xyz="0.0 0.0 0.0" rpy="0.0 0.0 0.0"/>
		<parent link="link_14_y"/>
		<child link="link_14"/>
		<axis xyz="0.0 0.0 1.0"/>
		<dynamics damping="0.005"/>
	</joint>

	<joint name="joint_15_x" type="revolute">
		<origin xyz="0.0 0.0 -0.05" rpy="0.0 0.0 0.0"/>
		<parent link="link_14"/>
		<child link="link_15_x"/>
		<axis xyz="1.0 0.0 0.0"/>
		<limit lower="-1.57" upper="1.57" effort="1000" velocity="20"/>
		<dynamics damping="0.005"/>
	</joint>

	<joint name="joint_15_y" type="revolute">
		<origin xyz="0.0 0.0 0.0" rpy="0.0 0.0 0.0"/>
		<parent link="link_15_x"/>
		<child link="link_15_y"/>
		<axis xyz="0.0 1.0 0.0"/>
		<limit lower="-1.57" upper="1.57" effort="1000" velocity="20"/>
		<dynamics damping="0.005"/>
	</joint>

	<joint name="joint_15_z" type="continuous">
		<origin xyz="0.0 0.0 0.0" rpy="0.0 0.0 0.0"/>
		<parent link="link_15_y"/>
		<child link="link_15"/>
		<axis xyz="0.0 0.0 1.0"/>
		<dynamics damping="0.005"/>
	</joint>

	<joint name="joint_16_x" type="revolute">
		<origin xyz="0.0 0.0 -0.05" rpy="0.0 0.0 0.0"/>
		<parent link="link_15"/>
		<child link="link_16_x"/>
		<axis xyz="1.0 0.0 0.0"/>
		<limit lower="-1.57" upper="1.57" effort="1000" velocity="20"/>
		<dynamics damping="0.005"/>
	</joint>

	<joint name="joint_16_y" type="revolute">
		<origin xyz="0.0 0.0 0.0" rpy="0.0 0.0 0.0"/>
		<parent link="link_16_x"/>
		<child link="link_16_y"/>
		<axis xyz="0.0 1.0 0.0"/>
		<limit lower="-1.57" upper="1.57" effort="1000" velocity="20"/>
		<dynamics damping="0.005"/>
	</joint>

	<joint name="joint_16_z" type="continuous">
		<origin xyz="0.0 0.0 0.0" rpy="0.0 0.0 0.0"/>
		<parent link="link_16_y"/>
		<child link="link_16"/>
		<axis xyz="0.0 0.0 1.0"/>
		<dynamics damping="0.005"/>
	</joint>

	<joint name="joint_17_x" type="revolute">
		<origin xyz="0.0 0.0 -0.05" rpy="0.0 0.0 0.0"/>
		<parent link="link_16"/>
		<child link="link_17_x"/>
		<axis xyz="1.0 0.0 0.0"/>
		<limit lower="-1.57" upper="1.57" effort="1000" velocity="20"/>
		<dynamics damping="0.005"/>
	</joint>

	<joint name="joint_17_y" type="revolute">
		<origin xyz="0.0 0.0 0.0" rpy="0.0 0.0 0.0"/>
		<parent link="link_17_x"/>
		<child link="link_17_y"/>
		<axis xyz="0.0 1.0 0.0"/>
		<limit lower="-1.57" upper="1.57" effort="1000" velocity="20"/>
		<dynamics damping="0.005"/>
	</joint>

	<joint name="joint_17_z" type="continuous">
		<origin xyz="0.0 0.0 0.0" rpy="0.0 0.0 0.0"/>
		<parent link="link_17_y"/>
		<child link="link_17"/>
		<axis xyz="0.0 0.0 1.0"/>
		<dynamics damping="0.005"/>
	</joint>

	<joint name="joint_18_x" type="revolute">
		<origin xyz="0.0 0.0 -0.05" rpy="0.0 0.0 0.0"/>
		<parent link="link_17"/>
		<child link="link_18_x"/>
		<axis xyz="1.0 0.0 0.0"/>
		<limit lower="-1.57" upper="1.57" effort="1000" velocity="20"/>
		<dynamics damping="0.005"/>
	</joint>

	<joint name="joint_18_y" type="revolute">
		<origin xyz="0.0 0.0 0.0" rpy="0.0 0.0 0.0"/>
		<parent link="link_18_x"/>
		<child link="link_18_y"/>
		<axis xyz="0.0 1.0 0.0"/>
		<limit lower="-1.57" upper="1.57" effort="1000" velocity="20"/>
		<dynamics damping="0.005"/>
	</joint>

	<joint name="joint_18_z" type="continuous">
		<origin xyz="0.0 0.0 0.0" rpy="0.0 0.0 0.0"/>
		<parent link="link_18_y"/>
		<child link="link_18"/>
		<axis xyz="0.0 0.0 1.0"/>
		<dynamics damping="0.005"/>
	</joint>

</robot>